Workbook
Name Wardrobes: 'Lists'!$A$2:$A$9
Name Categories: 'Lists'!$B$2:$B$33
Name Conditions: 'Lists'!$C$2:$C$6
Name Sizes: 'Lists'!$D$2:$D$88
Name Colors: 'Lists'!$E$2:$E$39
Name ItemStatus: 'Lists'!$F$2:$F$6
Name PurchaseStatus: 'Lists'!$G$2:$G$4
Name Platforms: 'Lists'!$H$2:$H$7

Sheet Lists
A1: Wardrobes | B1: Categories | C1: Conditions | D1: Sizes | E1: Colors | F1: Item Status | G1: Purchase Status | H1: Platforms
A2: Everyday | B2: Top | C2: New | D2: XXS | E2: Black | F2: Available | G2: Purchased | H2: In-person
A3: Work | B3: Bottom | C3: Like New | D3: XS | E3: White | F3: Rented | G3: Not purchased | H3: Venmo
A4: Casual | B4: Outerwear | C4: Good | D4: S | E4: Gray | F4: Cleaning | G4: Pending purchase | H4: Cash
A5: Formal | B5: Jacket | C5: Fair | D5: M | E5: Brown | F5: Repair | H5: Zelle
A6: Night Out | B6: Coat | C6: Needs Repair | D6: L | E6: Blue | F6: Retired | H6: PayPal
A7: Vacation | B7: Hoodie | D7: XL | E7: Navy | H7: Other
A8: Active | B8: Sweater | D8: XXL | E8: Green
A9: Seasonal | B9: T-Shirt | D9: XXXL | E9: Red
B10: Shirt | D10: One Size | E10: Pink
B11: Polo | D11: 00 | E11: Purple
B12: Dress | D12: 0 | E12: Yellow
B13: Suit | D13: 2 | E13: Orange
B14: Blazer | D14: 4 | E14: Beige
B15: Set | D15: 6 | E15: Tan
B16: Activewear | D16: 8 | E16: Cream
B17: Loungewear | D17: 10 | E17: Off-White
B18: Sleepwear | D18: 12 | E18: Charcoal
B19: Shoes | D19: 14 | E19: Chocolate
B20: Sneakers | D20: 16 | E20: Silver
B21: Boots | D21: 18 | E21: Light Blue
... B33: Tie | D33: 33 | E33: Hot Pink
D34: 34 | E34: Lavender
D35: 35 | E35: Gold
D36: 36 | E36: Multicolor
D37: 38 | E37: Patterned
D38: 40 | E38: Denim
D39: 42 | E39: Animal Print
D40: 44
D41: 46
D42: 48
D43: 50
D44: 52
D45: 54
D46: 56
D47: 58
D48: 60
D49: 28x30
D50: 28x32
D51: 30x30
...

Sheet Inventory
A1: Item ID | B1: Wardrobe Name | C1: Item Name | D1: Category | E1: Image URL | F1: Image | G1: Item Link | H1: Cost of Item ($) | I1: Rental Fee ($) | J1: Condition | K1: Size | L1: Color | M1: Brand | N1: Purchase Status | O1: Status | P1: Date Added | Q1: Extra Costs ($) | R1: Times Rented | S1: Total Revenue ($) | T1: Profit ($) | U1: Break-even Rentals | V1: Notes
A2: W001 | B2: Work | C2: Black Blazer | D2: Jacket | F2: =IF(E2="","",IMAGE(E2)) | H2: 120 | I2: 25 | J2: Like New | K2: M | L2: Black | M2: Zara | N2: Purchased | O2: Available | P2: 46012 | Q2: 0 | R2: =IF($C2="","",COUNTIF(Transactions!$C:$C,$A2)) | S2: =IF($C2="","",SUMIF(Transactions!$C:$C,$A2,Transactions!$R:$R)) | T2: =IF($C2="","",$S2-IF($N2="Purchased",$H2,0)-$Q2) | U2: =IF(OR($C2="",$I2=0),"",CEILING((IF($N2="Purchased",$H2,0)+$Q2)/$I2,1))
A3: W002 | F3: =IF(E3="","",IMAGE(E3)) | R3: =IF($C3="","",COUNTIF(Transactions!$C:$C,$A3)) | S3: =IF($C3="","",SUMIF(Transactions!$C:$C,$A3,Transactions!$R:$R)) | T3: =IF($C3="","",$S3-IF($N3="Purchased",$H3,0)-$Q3) | U3: =IF(OR($C3="",$I3=0),"",CEILING((IF($N3="Purchased",$H3,0)+$Q3)/$I3,1))
A4: W003 | F4: =IF(E4="","",IMAGE(E4)) | R4: =IF($C4="","",COUNTIF(Transactions!$C:$C,$A4)) | S4: =IF($C4="","",SUMIF(Transactions!$C:$C,$A4,Transactions!$R:$R)) | T4: =IF($C4="","",$S4-IF($N4="Purchased",$H4,0)-$Q4) | U4: =IF(OR($C4="",$I4=0),"",CEILING((IF($N4="Purchased",$H4,0)+$Q4)/$I4,1))
A5: W004 | F5: =IF(E5="","",IMAGE(E5)) | R5: =IF($C5="","",COUNTIF(Transactions!$C:$C,$A5)) | S5: =IF($C5="","",SUMIF(Transactions!$C:$C,$A5,Transactions!$R:$R)) | T5: =IF($C5="","",$S5-IF($N5="Purchased",$H5,0)-$Q5) | U5: =IF(OR($C5="",$I5=0),"",CEILING((IF($N5="Purchased",$H5,0)+$Q5)/$I5,1))
A6: W005 | F6: =IF(E6="","",IMAGE(E6)) | R6: =IF($C6="","",COUNTIF(Transactions!$C:$C,$A6)) | S6: =IF($C6="","",SUMIF(Transactions!$C:$C,$A6,Transactions!$R:$R)) | T6: =IF($C6="","",$S6-IF($N6="Purchased",$H6,0)-$Q6) | U6: =IF(OR($C6="",$I6=0),"",CEILING((IF($N6="Purchased",$H6,0)+$Q6)/$I6,1))
A7: W006 | F7: =IF(E7="","",IMAGE(E7)) | R7: =IF($C7="","",COUNTIF(Transactions!$C:$C,$A7)) | S7: =IF($C7="","",SUMIF(Transactions!$C:$C,$A7,Transactions!$R:$R)) | T7: =IF($C7="","",$S7-IF($N7="Purchased",$H7,0)-$Q7) | U7: =IF(OR($C7="",$I7=0),"",CEILING((IF($N7="Purchased",$H7,0)+$Q7)/$I7,1))
A8: W007 | F8: =IF(E8="","",IMAGE(E8)) | R8: =IF($C8="","",COUNTIF(Transactions!$C:$C,$A8)) | S8: =IF($C8="","",SUMIF(Transactions!$C:$C,$A8,Transactions!$R:$R)) | T8: =IF($C8="","",$S8-IF($N8="Purchased",$H8,0)-$Q8) | U8: =IF(OR($C8="",$I8=0),"",CEILING((IF($N8="Purchased",$H8,0)+$Q8)/$I8,1))
A9: W008 | F9: =IF(E9="","",IMAGE(E9)) | R9: =IF($C9="","",COUNTIF(Transactions!$C:$C,$A9)) | S9: =IF($C9="","",SUMIF(Transactions!$C:$C,$A9,Transactions!$R:$R)) | T9: =IF($C9="","",$S9-IF($N9="Purchased",$H9,0)-$Q9) | U9: =IF(OR($C9="",$I9=0),"",CEILING((IF($N9="Purchased",$H9,0)+$Q9)/$I9,1))
A10: W009 | F10: =IF(E10="","",IMAGE(E10)) | R10: =IF($C10="","",COUNTIF(Transactions!$C:$C,$A10)) | S10: =IF($C10="","",SUMIF(Transactions!$C:$C,$A10,Transactions!$R:$R)) | T10: =IF($C10="","",$S10-IF($N10="Purchased",$H10,0)-$Q10) | U10: =IF(OR($C10="",$I10=0),"",CEILING((IF($N10="Purchased",$H10,0)+$Q10)/$I10,1))
A11: W010 | F11: =IF(E11="","",IMAGE(E11)) | R11: =IF($C11="","",COUNTIF(Transactions!$C:$C,$A11)) | S11: =IF($C11="","",SUMIF(Transactions!$C:$C,$A11,Transactions!$R:$R)) | T11: =IF($C11="","",$S11-IF($N11="Purchased",$H11,0)-$Q11) | U11: =IF(OR($C11="",$I11=0),"",CEILING((IF($N11="Purchased",$H11,0)+$Q11)/$I11,1))
A12: W011 | F12: =IF(E12="","",IMAGE(E12)) | R12: =IF($C12="","",COUNTIF(Transactions!$C:$C,$A12)) | S12: =IF($C12="","",SUMIF(Transactions!$C:$C,$A12,Transactions!$R:$R)) | T12: =IF($C12="","",$S12-IF($N12="Purchased",$H12,0)-$Q12) | U12: =IF(OR($C12="",$I12=0),"",CEILING((IF($N12="Purchased",$H12,0)+$Q12)/$I12,1))
A13: W012 | F13: =IF(E13="","",IMAGE(E13)) | R13: =IF($C13="","",COUNTIF(Transactions!$C:$C,$A13)) | S13: =IF($C13="","",SUMIF(Transactions!$C:$C,$A13,Transactions!$R:$R)) | T13: =IF($C13="","",$S13-IF($N13="Purchased",$H13,0)-$Q13) | U13: =IF(OR($C13="",$I13=0),"",CEILING((IF($N13="Purchased",$H13,0)+$Q13)/$I13,1))
A14: W013 | F14: =IF(E14="","",IMAGE(E14)) | R14: =IF($C14="","",COUNTIF(Transactions!$C:$C,$A14)) | S14: =IF($C14="","",SUMIF(Transactions!$C:$C,$A14,Transactions!$R:$R)) | T14: =IF($C14="","",$S14-IF($N14="Purchased",$H14,0)-$Q14) | U14: =IF(OR($C14="",$I14=0),"",CEILING((IF($N14="Purchased",$H14,0)+$Q14)/$I14,1))
... A150: W149 | F150: =IF(E150="","",IMAGE(E150)) | R150: =IF($C150="","",COUNTIF(Transactions!$C:$C,$A150)) | S150: =IF($C150="","",SUMIF(Transactions!$C:$C,$A150,Transactions!$R:$R)) | T150: =IF($C150="","",$S150-IF($N150="Purchased",$H150,0)-$Q150) | U150: =IF(OR($C150="",$I150=0),"",CEILING((IF($N150="Purchased",$H150,0)+$Q150)/$I150,1))

Sheet Transactions
A1: Rental ID | B1: Booked Date | C1: Item ID | D1: Wardrobe | E1: Item Name | F1: Renter Name | G1: Platform | H1: Start Date | I1: End Date | J1: Days | K1: Base Rental Fee ($) | L1: Discount ($) | M1: Cleaning Fee ($) | N1: Damage Fee ($) | O1: Other Fees ($) | P1: Platform Fee ($) | Q1: Gross Revenue ($) | R1: Net Revenue ($) | S1: Notes
A2: T0001 | B2: 46012 | C2: W001 | D2: =IF($C2="","",VLOOKUP($C2,Inventory!$A$2:$V$150,2,FALSE)) | E2: =IF($C2="","",VLOOKUP($C2,Inventory!$A$2:$V$150,3,FALSE)) | F2: Example Renter | G2: Venmo | H2: 46012 | I2: 46012 | J2: =IF(OR($H2="",$I2=""),"",($I2-$H2)+1) | K2: =IF($C2="","",VLOOKUP($C2,Inventory!$A$2:$V$150,9,FALSE)) | L2: 0 | M2: 0 | N2: 0 | O2: 0 | P2: 0 | Q2: =IF($K2="","",$K2-$L2+$M2+$N2+$O2) | R2: =IF($Q2="","",$Q2-$P2)
A3: T0002 | D3: =IF($C3="","",VLOOKUP($C3,Inventory!$A$2:$V$150,2,FALSE)) | E3: =IF($C3="","",VLOOKUP($C3,Inventory!$A$2:$V$150,3,FALSE)) | J3: =IF(OR($H3="",$I3=""),"",($I3-$H3)+1) | K3: =IF($C3="","",VLOOKUP($C3,Inventory!$A$2:$V$150,9,FALSE)) | Q3: =IF($K3="","",$K3-$L3+$M3+$N3+$O3) | R3: =IF($Q3="","",$Q3-$P3)
A4: T0003 | D4: =IF($C4="","",VLOOKUP($C4,Inventory!$A$2:$V$150,2,FALSE)) | E4: =IF($C4="","",VLOOKUP($C4,Inventory!$A$2:$V$150,3,FALSE)) | J4: =IF(OR($H4="",$I4=""),"",($I4-$H4)+1) | K4: =IF($C4="","",VLOOKUP($C4,Inventory!$A$2:$V$150,9,FALSE)) | Q4: =IF($K4="","",$K4-$L4+$M4+$N4+$O4) | R4: =IF($Q4="","",$Q4-$P4)
A5: T0004 | D5: =IF($C5="","",VLOOKUP($C5,Inventory!$A$2:$V$150,2,FALSE)) | E5: =IF($C5="","",VLOOKUP($C5,Inventory!$A$2:$V$150,3,FALSE)) | J5: =IF(OR($H5="",$I5=""),"",($I5-$H5)+1) | K5: =IF($C5="","",VLOOKUP($C5,Inventory!$A$2:$V$150,9,FALSE)) | Q5: =IF($K5="","",$K5-$L5+$M5+$N5+$O5) | R5: =IF($Q5="","",$Q5-$P5)
A6: T0005 | D6: =IF($C6="","",VLOOKUP($C6,Inventory!$A$2:$V$150,2,FALSE)) | E6: =IF($C6="","",VLOOKUP($C6,Inventory!$A$2:$V$150,3,FALSE)) | J6: =IF(OR($H6="",$I6=""),"",($I6-$H6)+1) | K6: =IF($C6="","",VLOOKUP($C6,Inventory!$A$2:$V$150,9,FALSE)) | Q6: =IF($K6="","",$K6-$L6+$M6+$N6+$O6) | R6: =IF($Q6="","",$Q6-$P6)
A7: T0006 | D7: =IF($C7="","",VLOOKUP($C7,Inventory!$A$2:$V$150,2,FALSE)) | E7: =IF($C7="","",VLOOKUP($C7,Inventory!$A$2:$V$150,3,FALSE)) | J7: =IF(OR($H7="",$I7=""),"",($I7-$H7)+1) | K7: =IF($C7="","",VLOOKUP($C7,Inventory!$A$2:$V$150,9,FALSE)) | Q7: =IF($K7="","",$K7-$L7+$M7+$N7+$O7) | R7: =IF($Q7="","",$Q7-$P7)
A8: T0007 | D8: =IF($C8="","",VLOOKUP($C8,Inventory!$A$2:$V$150,2,FALSE)) | E8: =IF($C8="","",VLOOKUP($C8,Inventory!$A$2:$V$150,3,FALSE)) | J8: =IF(OR($H8="",$I8=""),"",($I8-$H8)+1) | K8: =IF($C8="","",VLOOKUP($C8,Inventory!$A$2:$V$150,9,FALSE)) | Q8: =IF($K8="","",$K8-$L8+$M8+$N8+$O8) | R8: =IF($Q8="","",$Q8-$P8)
A9: T0008 | D9: =IF($C9="","",VLOOKUP($C9,Inventory!$A$2:$V$150,2,FALSE)) | E9: =IF($C9="","",VLOOKUP($C9,Inventory!$A$2:$V$150,3,FALSE)) | J9: =IF(OR($H9="",$I9=""),"",($I9-$H9)+1) | K9: =IF($C9="","",VLOOKUP($C9,Inventory!$A$2:$V$150,9,FALSE)) | Q9: =IF($K9="","",$K9-$L9+$M9+$N9+$O9) | R9: =IF($Q9="","",$Q9-$P9)
A10: T0009 | D10: =IF($C10="","",VLOOKUP($C10,Inventory!$A$2:$V$150,2,FALSE)) | E10: =IF($C10="","",VLOOKUP($C10,Inventory!$A$2:$V$150,3,FALSE)) | J10: =IF(OR($H10="",$I10=""),"",($I10-$H10)+1) | K10: =IF($C10="","",VLOOKUP($C10,Inventory!$A$2:$V$150,9,FALSE)) | Q10: =IF($K10="","",$K10-$L10+$M10+$N10+$O10) | R10: =IF($Q10="","",$Q10-$P10)
A11: T0010 | D11: =IF($C11="","",VLOOKUP($C11,Inventory!$A$2:$V$150,2,FALSE)) | E11: =IF($C11="","",VLOOKUP($C11,Inventory!$A$2:$V$150,3,FALSE)) | J11: =IF(OR($H11="",$I11=""),"",($I11-$H11)+1) | K11: =IF($C11="","",VLOOKUP($C11,Inventory!$A$2:$V$150,9,FALSE)) | Q11: =IF($K11="","",$K11-$L11+$M11+$N11+$O11) | R11: =IF($Q11="","",$Q11-$P11)
A12: T0011 | D12: =IF($C12="","",VLOOKUP($C12,Inventory!$A$2:$V$150,2,FALSE)) | E12: =IF($C12="","",VLOOKUP($C12,Inventory!$A$2:$V$150,3,FALSE)) | J12: =IF(OR($H12="",$I12=""),"",($I12-$H12)+1) | K12: =IF($C12="","",VLOOKUP($C12,Inventory!$A$2:$V$150,9,FALSE)) | Q12: =IF($K12="","",$K12-$L12+$M12+$N12+$O12) | R12: =IF($Q12="","",$Q12-$P12)
A13: T0012 | D13: =IF($C13="","",VLOOKUP($C13,Inventory!$A$2:$V$150,2,FALSE)) | E13: =IF($C13="","",VLOOKUP($C13,Inventory!$A$2:$V$150,3,FALSE)) | J13: =IF(OR($H13="",$I13=""),"",($I13-$H13)+1) | K13: =IF($C13="","",VLOOKUP($C13,Inventory!$A$2:$V$150,9,FALSE)) | Q13: =IF($K13="","",$K13-$L13+$M13+$N13+$O13) | R13: =IF($Q13="","",$Q13-$P13)
A14: T0013 | D14: =IF($C14="","",VLOOKUP($C14,Inventory!$A$2:$V$150,2,FALSE)) | E14: =IF($C14="","",VLOOKUP($C14,Inventory!$A$2:$V$150,3,FALSE)) | J14: =IF(OR($H14="",$I14=""),"",($I14-$H14)+1) | K14: =IF($C14="","",VLOOKUP($C14,Inventory!$A$2:$V$150,9,FALSE)) | Q14: =IF($K14="","",$K14-$L14+$M14+$N14+$O14) | R14: =IF($Q14="","",$Q14-$P14)
... A150: T0149 | D150: =IF($C150="","",VLOOKUP($C150,Inventory!$A$2:$V$150,2,FALSE)) | E150: =IF($C150="","",VLOOKUP($C150,Inventory!$A$2:$V$150,3,FALSE)) | J150: =IF(OR($H150="",$I150=""),"",($I150-$H150)+1) | K150: =IF($C150="","",VLOOKUP($C150,Inventory!$A$2:$V$150,9,FALSE)) | Q150: =IF($K150="","",$K150-$L150+$M150+$N150+$O150) | R150: =IF($Q150="","",$Q150-$P150)

Sheet Wardrobe View
A1: Select wardrobe:
A3: Items in selected wardrobe (auto):
A5: Item ID | B5: Wardrobe Name | C5: Item Name | D5: Category | E5: Image URL | F5: Image | G5: Item Link | H5: Cost of Item ($) | I5: Rental Fee ($) | J5: Condition | K5: Size | L5: Color | M5: Brand | N5: Purchase Status | O5: Status | P5: Date Added | Q5: Extra Costs ($) | R5: Times Rented | S5: Total Revenue ($) | T5: Profit ($) | U5: Break-even Rentals | V5: Notes | X5: match_row
A6: =IF($X6="","",INDEX(Inventory!$A$2:$V$150,$X6,1)) | B6: =IF($X6="","",INDEX(Inventory!$A$2:$V$150,$X6,2)) | C6: =IF($X6="","",INDEX(Inventory!$A$2:$V$150,$X6,3)) | D6: =IF($X6="","",INDEX(Inventory!$A$2:$V$150,$X6,4)) | E6: =IF($X6="","",INDEX(Inventory!$A$2:$V$150,$X6,5)) | F6: =IF($X6="","",INDEX(Inventory!$A$2:$V$150,$X6,6)) | G6: =IF($X6="","",INDEX(Inventory!$A$2:$V$150,$X6,7)) | H6: =IF($X6="","",INDEX(Inventory!$A$2:$V$150,$X6,8)) | I6: =IF($X6="","",INDEX(Inventory!$A$2:$V$150,$X6,9)) | J6: =IF($X6="","",INDEX(Inventory!$A$2:$V$150,$X6,10)) | K6: =IF($X6="","",INDEX(Inventory!$A$2:$V$150,$X6,11)) | L6: =IF($X6="","",INDEX(Inventory!$A$2:$V$150,$X6,12)) | M6: =IF($X6="","",INDEX(Inventory!$A$2:$V$150,$X6,13)) | N6: =IF($X6="","",INDEX(Inventory!$A$2:$V$150,$X6,14)) | O6: =IF($X6="","",INDEX(Inventory!$A$2:$V$150,$X6,15)) | P6: =IF($X6="","",INDEX(Inventory!$A$2:$V$150,$X6,16)) | Q6: =IF($X6="","",INDEX(Inventory!$A$2:$V$150,$X6,17)) | R6: =IF($X6="","",INDEX(Inventory!$A$2:$V$150,$X6,18)) | S6: =IF($X6="","",INDEX(Inventory!$A$2:$V$150,$X6,19)) | T6: =IF($X6="","",INDEX(Inventory!$A$2:$V$150,$X6,20)) | U6: =IF($X6="","",INDEX(Inventory!$A$2:$V$150,$X6,21)) | V6: =IF($X6="","",INDEX(Inventory!$A$2:$V$150,$X6,22)) | X6: =IF($B$1="","",IFERROR(AGGREGATE(15,6,(ROW(Inventory!$B$2:$B$150)-ROW(Inventory!$B$2)+1)/(Inventory!$B$2:$B$150=$B$1),ROWS($A$6:A6)), ""))
A7: =IF($X7="","",INDEX(Inventory!$A$2:$V$150,$X7,1)) | B7: =IF($X7="","",INDEX(Inventory!$A$2:$V$150,$X7,2)) | C7: =IF($X7="","",INDEX(Inventory!$A$2:$V$150,$X7,3)) | D7: =IF($X7="","",INDEX(Inventory!$A$2:$V$150,$X7,4)) | E7: =IF($X7="","",INDEX(Inventory!$A$2:$V$150,$X7,5)) | F7: =IF($X7="","",INDEX(Inventory!$A$2:$V$150,$X7,6)) | G7: =IF($X7="","",INDEX(Inventory!$A$2:$V$150,$X7,7)) | H7: =IF($X7="","",INDEX(Inventory!$A$2:$V$150,$X7,8)) | I7: =IF($X7="","",INDEX(Inventory!$A$2:$V$150,$X7,9)) | J7: =IF($X7="","",INDEX(Inventory!$A$2:$V$150,$X7,10)) | K7: =IF($X7="","",INDEX(Inventory!$A$2:$V$150,$X7,11)) | L7: =IF($X7="","",INDEX(Inventory!$A$2:$V$150,$X7,12)) | M7: =IF($X7="","",INDEX(Inventory!$A$2:$V$150,$X7,13)) | N7: =IF($X7="","",INDEX(Inventory!$A$2:$V$150,$X7,14)) | O7: =IF($X7="","",INDEX(Inventory!$A$2:$V$150,$X7,15)) | P7: =IF($X7="","",INDEX(Inventory!$A$2:$V$150,$X7,16)) | Q7: =IF($X7="","",INDEX(Inventory!$A$2:$V$150,$X7,17)) | R7: =IF($X7="","",INDEX(Inventory!$A$2:$V$150,$X7,18)) | S7: =IF($X7="","",INDEX(Inventory!$A$2:$V$150,$X7,19)) | T7: =IF($X7="","",INDEX(Inventory!$A$2:$V$150,$X7,20)) | U7: =IF($X7="","",INDEX(Inventory!$A$2:$V$150,$X7,21)) | V7: =IF($X7="","",INDEX(Inventory!$A$2:$V$150,$X7,22)) | X7: =IF($B$1="","",IFERROR(AGGREGATE(15,6,(ROW(Inventory!$B$2:$B$150)-ROW(Inventory!$B$2)+1)/(Inventory!$B$2:$B$150=$B$1),ROWS($A$6:A7)), ""))
A8: =IF($X8="","",INDEX(Inventory!$A$2:$V$150,$X8,1)) | B8: =IF($X8="","",INDEX(Inventory!$A$2:$V$150,$X8,2)) | C8: =IF($X8="","",INDEX(Inventory!$A$2:$V$150,$X8,3)) | D8: =IF($X8="","",INDEX(Inventory!$A$2:$V$150,$X8,4)) | E8: =IF($X8="","",INDEX(Inventory!$A$2:$V$150,$X8,5)) | F8: =IF($X8="","",INDEX(Inventory!$A$2:$V$150,$X8,6)) | G8: =IF($X8="","",INDEX(Inventory!$A$2:$V$150,$X8,7)) | H8: =IF($X8="","",INDEX(Inventory!$A$2:$V$150,$X8,8)) | I8: =IF($X8="","",INDEX(Inventory!$A$2:$V$150,$X8,9)) | J8: =IF($X8="","",INDEX(Inventory!$A$2:$V$150,$X8,10)) | K8: =IF($X8="","",INDEX(Inventory!$A$2:$V$150,$X8,11)) | L8: =IF($X8="","",INDEX(Inventory!$A$2:$V$150,$X8,12)) | M8: =IF($X8="","",INDEX(Inventory!$A$2:$V$150,$X8,13)) | N8: =IF($X8="","",INDEX(Inventory!$A$2:$V$150,$X8,14)) | O8: =IF($X8="","",INDEX(Inventory!$A$2:$V$150,$X8,15)) | P8: =IF($X8="","",INDEX(Inventory!$A$2:$V$150,$X8,16)) | Q8: =IF($X8="","",INDEX(Inventory!$A$2:$V$150,$X8,17)) | R8: =IF($X8="","",INDEX(Inventory!$A$2:$V$150,$X8,18)) | S8: =IF($X8="","",INDEX(Inventory!$A$2:$V$150,$X8,19)) | T8: =IF($X8="","",INDEX(Inventory!$A$2:$V$150,$X8,20)) | U8: =IF($X8="","",INDEX(Inventory!$A$2:$V$150,$X8,21)) | V8: =IF($X8="","",INDEX(Inventory!$A$2:$V$150,$X8,22)) | X8: =IF($B$1="","",IFERROR(AGGREGATE(15,6,(ROW(Inventory!$B$2:$B$150)-ROW(Inventory!$B$2)+1)/(Inventory!$B$2:$B$150=$B$1),ROWS($A$6:A8)), ""))
A9: =IF($X9="","",INDEX(Inventory!$A$2:$V$150,$X9,1)) | B9: =IF($X9="","",INDEX(Inventory!$A$2:$V$150,$X9,2)) | C9: =IF($X9="","",INDEX(Inventory!$A$2:$V$150,$X9,3)) | D9: =IF($X9="","",INDEX(Inventory!$A$2:$V$150,$X9,4)) | E9: =IF($X9="","",INDEX(Inventory!$A$2:$V$150,$X9,5)) | F9: =IF($X9="","",INDEX(Inventory!$A$2:$V$150,$X9,6)) | G9: =IF($X9="","",INDEX(Inventory!$A$2:$V$150,$X9,7)) | H9: =IF($X9="","",INDEX(Inventory!$A$2:$V$150,$X9,8)) | I9: =IF($X9="","",INDEX(Inventory!$A$2:$V$150,$X9,9)) | J9: =IF($X9="","",INDEX(Inventory!$A$2:$V$150,$X9,10)) | K9: =IF($X9="","",INDEX(Inventory!$A$2:$V$150,$X9,11)) | L9: =IF($X9="","",INDEX(Inventory!$A$2:$V$150,$X9,12)) | M9: =IF($X9="","",INDEX(Inventory!$A$2:$V$150,$X9,13)) | N9: =IF($X9="","",INDEX(Inventory!$A$2:$V$150,$X9,14)) | O9: =IF($X9="","",INDEX(Inventory!$A$2:$V$150,$X9,15)) | P9: =IF($X9="","",INDEX(Inventory!$A$2:$V$150,$X9,16)) | Q9: =IF($X9="","",INDEX(Inventory!$A$2:$V$150,$X9,17)) | R9: =IF($X9="","",INDEX(Inventory!$A$2:$V$150,$X9,18)) | S9: =IF($X9="","",INDEX(Inventory!$A$2:$V$150,$X9,19)) | T9: =IF($X9="","",INDEX(Inventory!$A$2:$V$150,$X9,20)) | U9: =IF($X9="","",INDEX(Inventory!$A$2:$V$150,$X9,21)) | V9: =IF($X9="","",INDEX(Inventory!$A$2:$V$150,$X9,22)) | X9: =IF($B$1="","",IFERROR(AGGREGATE(15,6,(ROW(Inventory!$B$2:$B$150)-ROW(Inventory!$B$2)+1)/(Inventory!$B$2:$B$150=$B$1),ROWS($A$6:A9)), ""))
A10: =IF($X10="","",INDEX(Inventory!$A$2:$V$150,$X10,1)) | B10: =IF($X10="","",INDEX(Inventory!$A$2:$V$150,$X10,2)) | C10: =IF($X10="","",INDEX(Inventory!$A$2:$V$150,$X10,3)) | D10: =IF($X10="","",INDEX(Inventory!$A$2:$V$150,$X10,4)) | E10: =IF($X10="","",INDEX(Inventory!$A$2:$V$150,$X10,5)) | F10: =IF($X10="","",INDEX(Inventory!$A$2:$V$150,$X10,6)) | G10: =IF($X10="","",INDEX(Inventory!$A$2:$V$150,$X10,7)) | H10: =IF($X10="","",INDEX(Inventory!$A$2:$V$150,$X10,8)) | I10: =IF($X10="","",INDEX(Inventory!$A$2:$V$150,$X10,9)) | J10: =IF($X10="","",INDEX(Inventory!$A$2:$V$150,$X10,10)) | K10: =IF($X10="","",INDEX(Inventory!$A$2:$V$150,$X10,11)) | L10: =IF($X10="","",INDEX(Inventory!$A$2:$V$150,$X10,12)) | M10: =IF($X10="","",INDEX(Inventory!$A$2:$V$150,$X10,13)) | N10: =IF($X10="","",INDEX(Inventory!$A$2:$V$150,$X10,14)) | O10: =IF($X10="","",INDEX(Inventory!$A$2:$V$150,$X10,15)) | P10: =IF($X10="","",INDEX(Inventory!$A$2:$V$150,$X10,16)) | Q10: =IF($X10="","",INDEX(Inventory!$A$2:$V$150,$X10,17)) | R10: =IF($X10="","",INDEX(Inventory!$A$2:$V$150,$X10,18)) | S10: =IF($X10="","",INDEX(Inventory!$A$2:$V$150,$X10,19)) | T10: =IF($X10="","",INDEX(Inventory!$A$2:$V$150,$X10,20)) | U10: =IF($X10="","",INDEX(Inventory!$A$2:$V$150,$X10,21)) | V10: =IF($X10="","",INDEX(Inventory!$A$2:$V$150,$X10,22)) | X10: =IF($B$1="","",IFERROR(AGGREGATE(15,6,(ROW(Inventory!$B$2:$B$150)-ROW(Inventory!$B$2)+1)/(Inventory!$B$2:$B$150=$B$1),ROWS($A$6:A10)), ""))
A11: =IF($X11="","",INDEX(Inventory!$A$2:$V$150,$X11,1)) | B11: =IF($X11="","",INDEX(Inventory!$A$2:$V$150,$X11,2)) | C11: =IF($X11="","",INDEX(Inventory!$A$2:$V$150,$X11,3)) | D11: =IF($X11="","",INDEX(Inventory!$A$2:$V$150,$X11,4)) | E11: =IF($X11="","",INDEX(Inventory!$A$2:$V$150,$X11,5)) | F11: =IF($X11="","",INDEX(Inventory!$A$2:$V$150,$X11,6)) | G11: =IF($X11="","",INDEX(Inventory!$A$2:$V$150,$X11,7)) | H11: =IF($X11="","",INDEX(Inventory!$A$2:$V$150,$X11,8)) | I11: =IF($X11="","",INDEX(Inventory!$A$2:$V$150,$X11,9)) | J11: =IF($X11="","",INDEX(Inventory!$A$2:$V$150,$X11,10)) | K11: =IF($X11="","",INDEX(Inventory!$A$2:$V$150,$X11,11)) | L11: =IF($X11="","",INDEX(Inventory!$A$2:$V$150,$X11,12)) | M11: =IF($X11="","",INDEX(Inventory!$A$2:$V$150,$X11,13)) | N11: =IF($X11="","",INDEX(Inventory!$A$2:$V$150,$X11,14)) | O11: =IF($X11="","",INDEX(Inventory!$A$2:$V$150,$X11,15)) | P11: =IF($X11="","",INDEX(Inventory!$A$2:$V$150,$X11,16)) | Q11: =IF($X11="","",INDEX(Inventory!$A$2:$V$150,$X11,17)) | R11: =IF($X11="","",INDEX(Inventory!$A$2:$V$150,$X11,18)) | S11: =IF($X11="","",INDEX(Inventory!$A$2:$V$150,$X11,19)) | T11: =IF($X11="","",INDEX(Inventory!$A$2:$V$150,$X11,20)) | U11: =IF($X11="","",INDEX(Inventory!$A$2:$V$150,$X11,21)) | V11: =IF($X11="","",INDEX(Inventory!$A$2:$V$150,$X11,22)) | X11: =IF($B$1="","",IFERROR(AGGREGATE(15,6,(ROW(Inventory!$B$2:$B$150)-ROW(Inventory!$B$2)+1)/(Inventory!$B$2:$B$150=$B$1),ROWS($A$6:A11)), ""))
A12: =IF($X12="","",INDEX(Inventory!$A$2:$V$150,$X12,1)) | B12: =IF($X12="","",INDEX(Inventory!$A$2:$V$150,$X12,2)) | C12: =IF($X12="","",INDEX(Inventory!$A$2:$V$150,$X12,3)) | D12: =IF($X12="","",INDEX(Inventory!$A$2:$V$150,$X12,4)) | E12: =IF($X12="","",INDEX(Inventory!$A$2:$V$150,$X12,5)) | F12: =IF($X12="","",INDEX(Inventory!$A$2:$V$150,$X12,6)) | G12: =IF($X12="","",INDEX(Inventory!$A$2:$V$150,$X12,7)) | H12: =IF($X12="","",INDEX(Inventory!$A$2:$V$150,$X12,8)) | I12: =IF($X12="","",INDEX(Inventory!$A$2:$V$150,$X12,9)) | J12: =IF($X12="","",INDEX(Inventory!$A$2:$V$150,$X12,10)) | K12: =IF($X12="","",INDEX(Inventory!$A$2:$V$150,$X12,11)) | L12: =IF($X12="","",INDEX(Inventory!$A$2:$V$150,$X12,12)) | M12: =IF($X12="","",INDEX(Inventory!$A$2:$V$150,$X12,13)) | N12: =IF($X12="","",INDEX(Inventory!$A$2:$V$150,$X12,14)) | O12: =IF($X12="","",INDEX(Inventory!$A$2:$V$150,$X12,15)) | P12: =IF($X12="","",INDEX(Inventory!$A$2:$V$150,$X12,16)) | Q12: =IF($X12="","",INDEX(Inventory!$A$2:$V$150,$X12,17)) | R12: =IF($X12="","",INDEX(Inventory!$A$2:$V$150,$X12,18)) | S12: =IF($X12="","",INDEX(Inventory!$A$2:$V$150,$X12,19)) | T12: =IF($X12="","",INDEX(Inventory!$A$2:$V$150,$X12,20)) | U12: =IF($X12="","",INDEX(Inventory!$A$2:$V$150,$X12,21)) | V12: =IF($X12="","",INDEX(Inventory!$A$2:$V$150,$X12,22)) | X12: =IF($B$1="","",IFERROR(AGGREGATE(15,6,(ROW(Inventory!$B$2:$B$150)-ROW(Inventory!$B$2)+1)/(Inventory!$B$2:$B$150=$B$1),ROWS($A$6:A12)), ""))
A13: =IF($X13="","",INDEX(Inventory!$A$2:$V$150,$X13,1)) | B13: =IF($X13="","",INDEX(Inventory!$A$2:$V$150,$X13,2)) | C13: =IF($X13="","",INDEX(Inventory!$A$2:$V$150,$X13,3)) | D13: =IF($X13="","",INDEX(Inventory!$A$2:$V$150,$X13,4)) | E13: =IF($X13="","",INDEX(Inventory!$A$2:$V$150,$X13,5)) | F13: =IF($X13="","",INDEX(Inventory!$A$2:$V$150,$X13,6)) | G13: =IF($X13="","",INDEX(Inventory!$A$2:$V$150,$X13,7)) | H13: =IF($X13="","",INDEX(Inventory!$A$2:$V$150,$X13,8)) | I13: =IF($X13="","",INDEX(Inventory!$A$2:$V$150,$X13,9)) | J13: =IF($X13="","",INDEX(Inventory!$A$2:$V$150,$X13,10)) | K13: =IF($X13="","",INDEX(Inventory!$A$2:$V$150,$X13,11)) | L13: =IF($X13="","",INDEX(Inventory!$A$2:$V$150,$X13,12)) | M13: =IF($X13="","",INDEX(Inventory!$A$2:$V$150,$X13,13)) | N13: =IF($X13="","",INDEX(Inventory!$A$2:$V$150,$X13,14)) | O13: =IF($X13="","",INDEX(Inventory!$A$2:$V$150,$X13,15)) | P13: =IF($X13="","",INDEX(Inventory!$A$2:$V$150,$X13,16)) | Q13: =IF($X13="","",INDEX(Inventory!$A$2:$V$150,$X13,17)) | R13: =IF($X13="","",INDEX(Inventory!$A$2:$V$150,$X13,18)) | S13: =IF($X13="","",INDEX(Inventory!$A$2:$V$150,$X13,19)) | T13: =IF($X13="","",INDEX(Inventory!$A$2:$V$150,$X13,20)) | U13: =IF($X13="","",INDEX(Inventory!$A$2:$V$150,$X13,21)) | V13: =IF($X13="","",INDEX(Inventory!$A$2:$V$150,$X13,22)) | X13: =IF($B$1="","",IFERROR(AGGREGATE(15,6,(ROW(Inventory!$B$2:$B$150)-ROW(Inventory!$B$2)+1)/(Inventory!$B$2:$B$150=$B$1),ROWS($A$6:A13)), ""))
A14: =IF($X14="","",INDEX(Inventory!$A$2:$V$150,$X14,1)) | B14: =IF($X14="","",INDEX(Inventory!$A$2:$V$150,$X14,2)) | C14: =IF($X14="","",INDEX(Inventory!$A$2:$V$150,$X14,3)) | D14: =IF($X14="","",INDEX(Inventory!$A$2:$V$150,$X14,4)) | E14: =IF($X14="","",INDEX(Inventory!$A$2:$V$150,$X14,5)) | F14: =IF($X14="","",INDEX(Inventory!$A$2:$V$150,$X14,6)) | G14: =IF($X14="","",INDEX(Inventory!$A$2:$V$150,$X14,7)) | H14: =IF($X14="","",INDEX(Inventory!$A$2:$V$150,$X14,8)) | I14: =IF($X14="","",INDEX(Inventory!$A$2:$V$150,$X14,9)) | J14: =IF($X14="","",INDEX(Inventory!$A$2:$V$150,$X14,10)) | K14: =IF($X14="","",INDEX(Inventory!$A$2:$V$150,$X14,11)) | L14: =IF($X14="","",INDEX(Inventory!$A$2:$V$150,$X14,12)) | M14: =IF($X14="","",INDEX(Inventory!$A$2:$V$150,$X14,13)) | N14: =IF($X14="","",INDEX(Inventory!$A$2:$V$150,$X14,14)) | O14: =IF($X14="","",INDEX(Inventory!$A$2:$V$150,$X14,15)) | P14: =IF($X14="","",INDEX(Inventory!$A$2:$V$150,$X14,16)) | Q14: =IF($X14="","",INDEX(Inventory!$A$2:$V$150,$X14,17)) | R14: =IF($X14="","",INDEX(Inventory!$A$2:$V$150,$X14,18)) | S14: =IF($X14="","",INDEX(Inventory!$A$2:$V$150,$X14,19)) | T14: =IF($X14="","",INDEX(Inventory!$A$2:$V$150,$X14,20)) | U14: =IF($X14="","",INDEX(Inventory!$A$2:$V$150,$X14,21)) | V14: =IF($X14="","",INDEX(Inventory!$A$2:$V$150,$X14,22)) | X14: =IF($B$1="","",IFERROR(AGGREGATE(15,6,(ROW(Inventory!$B$2:$B$150)-ROW(Inventory!$B$2)+1)/(Inventory!$B$2:$B$150=$B$1),ROWS($A$6:A14)), ""))
A15: =IF($X15="","",INDEX(Inventory!$A$2:$V$150,$X15,1)) | B15: =IF($X15="","",INDEX(Inventory!$A$2:$V$150,$X15,2)) | C15: =IF($X15="","",INDEX(Inventory!$A$2:$V$150,$X15,3)) | D15: =IF($X15="","",INDEX(Inventory!$A$2:$V$150,$X15,4)) | E15: =IF($X15="","",INDEX(Inventory!$A$2:$V$150,$X15,5)) | F15: =IF($X15="","",INDEX(Inventory!$A$2:$V$150,$X15,6)) | G15: =IF($X15="","",INDEX(Inventory!$A$2:$V$150,$X15,7)) | H15: =IF($X15="","",INDEX(Inventory!$A$2:$V$150,$X15,8)) | I15: =IF($X15="","",INDEX(Inventory!$A$2:$V$150,$X15,9)) | J15: =IF($X15="","",INDEX(Inventory!$A$2:$V$150,$X15,10)) | K15: =IF($X15="","",INDEX(Inventory!$A$2:$V$150,$X15,11)) | L15: =IF($X15="","",INDEX(Inventory!$A$2:$V$150,$X15,12)) | M15: =IF($X15="","",INDEX(Inventory!$A$2:$V$150,$X15,13)) | N15: =IF($X15="","",INDEX(Inventory!$A$2:$V$150,$X15,14)) | O15: =IF($X15="","",INDEX(Inventory!$A$2:$V$150,$X15,15)) | P15: =IF($X15="","",INDEX(Inventory!$A$2:$V$150,$X15,16)) | Q15: =IF($X15="","",INDEX(Inventory!$A$2:$V$150,$X15,17)) | R15: =IF($X15="","",INDEX(Inventory!$A$2:$V$150,$X15,18)) | S15: =IF($X15="","",INDEX(Inventory!$A$2:$V$150,$X15,19)) | T15: =IF($X15="","",INDEX(Inventory!$A$2:$V$150,$X15,20)) | U15: =IF($X15="","",INDEX(Inventory!$A$2:$V$150,$X15,21)) | V15: =IF($X15="","",INDEX(Inventory!$A$2:$V$150,$X15,22)) | X15: =IF($B$1="","",IFERROR(AGGREGATE(15,6,(ROW(Inventory!$B$2:$B$150)-ROW(Inventory!$B$2)+1)/(Inventory!$B$2:$B$150=$B$1),ROWS($A$6:A15)), ""))
A16: =IF($X16="","",INDEX(Inventory!$A$2:$V$150,$X16,1)) | B16: =IF($X16="","",INDEX(Inventory!$A$2:$V$150,$X16,2)) | C16: =IF($X16="","",INDEX(Inventory!$A$2:$V$150,$X16,3)) | D16: =IF($X16="","",INDEX(Inventory!$A$2:$V$150,$X16,4)) | E16: =IF($X16="","",INDEX(Inventory!$A$2:$V$150,$X16,5)) | F16: =IF($X16="","",INDEX(Inventory!$A$2:$V$150,$X16,6)) | G16: =IF($X16="","",INDEX(Inventory!$A$2:$V$150,$X16,7)) | H16: =IF($X16="","",INDEX(Inventory!$A$2:$V$150,$X16,8)) | I16: =IF($X16="","",INDEX(Inventory!$A$2:$V$150,$X16,9)) | J16: =IF($X16="","",INDEX(Inventory!$A$2:$V$150,$X16,10)) | K16: =IF($X16="","",INDEX(Inventory!$A$2:$V$150,$X16,11)) | L16: =IF($X16="","",INDEX(Inventory!$A$2:$V$150,$X16,12)) | M16: =IF($X16="","",INDEX(Inventory!$A$2:$V$150,$X16,13)) | N16: =IF($X16="","",INDEX(Inventory!$A$2:$V$150,$X16,14)) | O16: =IF($X16="","",INDEX(Inventory!$A$2:$V$150,$X16,15)) | P16: =IF($X16="","",INDEX(Inventory!$A$2:$V$150,$X16,16)) | Q16: =IF($X16="","",INDEX(Inventory!$A$2:$V$150,$X16,17)) | R16: =IF($X16="","",INDEX(Inventory!$A$2:$V$150,$X16,18)) | S16: =IF($X16="","",INDEX(Inventory!$A$2:$V$150,$X16,19)) | T16: =IF($X16="","",INDEX(Inventory!$A$2:$V$150,$X16,20)) | U16: =IF($X16="","",INDEX(Inventory!$A$2:$V$150,$X16,21)) | V16: =IF($X16="","",INDEX(Inventory!$A$2:$V$150,$X16,22)) | X16: =IF($B$1="","",IFERROR(AGGREGATE(15,6,(ROW(Inventory!$B$2:$B$150)-ROW(Inventory!$B$2)+1)/(Inventory!$B$2:$B$150=$B$1),ROWS($A$6:A16)), ""))
A17: =IF($X17="","",INDEX(Inventory!$A$2:$V$150,$X17,1)) | B17: =IF($X17="","",INDEX(Inventory!$A$2:$V$150,$X17,2)) | C17: =IF($X17="","",INDEX(Inventory!$A$2:$V$150,$X17,3)) | D17: =IF($X17="","",INDEX(Inventory!$A$2:$V$150,$X17,4)) | E17: =IF($X17="","",INDEX(Inventory!$A$2:$V$150,$X17,5)) | F17: =IF($X17="","",INDEX(Inventory!$A$2:$V$150,$X17,6)) | G17: =IF($X17="","",INDEX(Inventory!$A$2:$V$150,$X17,7)) | H17: =IF($X17="","",INDEX(Inventory!$A$2:$V$150,$X17,8)) | I17: =IF($X17="","",INDEX(Inventory!$A$2:$V$150,$X17,9)) | J17: =IF($X17="","",INDEX(Inventory!$A$2:$V$150,$X17,10)) | K17: =IF($X17="","",INDEX(Inventory!$A$2:$V$150,$X17,11)) | L17: =IF($X17="","",INDEX(Inventory!$A$2:$V$150,$X17,12)) | M17: =IF($X17="","",INDEX(Inventory!$A$2:$V$150,$X17,13)) | N17: =IF($X17="","",INDEX(Inventory!$A$2:$V$150,$X17,14)) | O17: =IF($X17="","",INDEX(Inventory!$A$2:$V$150,$X17,15)) | P17: =IF($X17="","",INDEX(Inventory!$A$2:$V$150,$X17,16)) | Q17: =IF($X17="","",INDEX(Inventory!$A$2:$V$150,$X17,17)) | R17: =IF($X17="","",INDEX(Inventory!$A$2:$V$150,$X17,18)) | S17: =IF($X17="","",INDEX(Inventory!$A$2:$V$150,$X17,19)) | T17: =IF($X17="","",INDEX(Inventory!$A$2:$V$150,$X17,20)) | U17: =IF($X17="","",INDEX(Inventory!$A$2:$V$150,$X17,21)) | V17: =IF($X17="","",INDEX(Inventory!$A$2:$V$150,$X17,22)) | X17: =IF($B$1="","",IFERROR(AGGREGATE(15,6,(ROW(Inventory!$B$2:$B$150)-ROW(Inventory!$B$2)+1)/(Inventory!$B$2:$B$150=$B$1),ROWS($A$6:A17)), ""))
... A105: =IF($X105="","",INDEX(Inventory!$A$2:$V$150,$X105,1)) | B105: =IF($X105="","",INDEX(Inventory!$A$2:$V$150,$X105,2)) | C105: =IF($X105="","",INDEX(Inventory!$A$2:$V$150,$X105,3)) | D105: =IF($X105="","",INDEX(Inventory!$A$2:$V$150,$X105,4)) | E105: =IF($X105="","",INDEX(Inventory!$A$2:$V$150,$X105,5)) | F105: =IF($X105="","",INDEX(Inventory!$A$2:$V$150,$X105,6)) | G105: =IF($X105="","",INDEX(Inventory!$A$2:$V$150,$X105,7)) | H105: =IF($X105="","",INDEX(Inventory!$A$2:$V$150,$X105,8)) | I105: =IF($X105="","",INDEX(Inventory!$A$2:$V$150,$X105,9)) | J105: =IF($X105="","",INDEX(Inventory!$A$2:$V$150,$X105,10)) | K105: =IF($X105="","",INDEX(Inventory!$A$2:$V$150,$X105,11)) | L105: =IF($X105="","",INDEX(Inventory!$A$2:$V$150,$X105,12)) | M105: =IF($X105="","",INDEX(Inventory!$A$2:$V$150,$X105,13)) | N105: =IF($X105="","",INDEX(Inventory!$A$2:$V$150,$X105,14)) | O105: =IF($X105="","",INDEX(Inventory!$A$2:$V$150,$X105,15)) | P105: =IF($X105="","",INDEX(Inventory!$A$2:$V$150,$X105,16)) | Q105: =IF($X105="","",INDEX(Inventory!$A$2:$V$150,$X105,17)) | R105: =IF($X105="","",INDEX(Inventory!$A$2:$V$150,$X105,18)) | S105: =IF($X105="","",INDEX(Inventory!$A$2:$V$150,$X105,19)) | T105: =IF($X105="","",INDEX(Inventory!$A$2:$V$150,$X105,20)) | U105: =IF($X105="","",INDEX(Inventory!$A$2:$V$150,$X105,21)) | V105: =IF($X105="","",INDEX(Inventory!$A$2:$V$150,$X105,22)) | X105: =IF($B$1="","",IFERROR(AGGREGATE(15,6,(ROW(Inventory!$B$2:$B$150)-ROW(Inventory!$B$2)+1)/(Inventory!$B$2:$B$150=$B$1),ROWS($A$6:A105)), ""))

Sheet Dashboard
A1: Wardrobe Dashboard
A3: Wardrobe | B3: # Items | C3: Total Revenue ($) | D3: Total Profit ($) | E3: Avg Rental Fee ($)
A4: Everyday | B4: =COUNTIF(Inventory!$B:$B,$A4) | C4: =SUMIF(Inventory!$B:$B,$A4,Inventory!$S:$S) | D4: =SUMIF(Inventory!$B:$B,$A4,Inventory!$T:$T) | E4: =IFERROR(AVERAGEIF(Inventory!$B:$B,$A4,Inventory!$I:$I),0)
A5: Work | B5: =COUNTIF(Inventory!$B:$B,$A5) | C5: =SUMIF(Inventory!$B:$B,$A5,Inventory!$S:$S) | D5: =SUMIF(Inventory!$B:$B,$A5,Inventory!$T:$T) | E5: =IFERROR(AVERAGEIF(Inventory!$B:$B,$A5,Inventory!$I:$I),0)
A6: Casual | B6: =COUNTIF(Inventory!$B:$B,$A6) | C6: =SUMIF(Inventory!$B:$B,$A6,Inventory!$S:$S) | D6: =SUMIF(Inventory!$B:$B,$A6,Inventory!$T:$T) | E6: =IFERROR(AVERAGEIF(Inventory!$B:$B,$A6,Inventory!$I:$I),0)
A7: Formal | B7: =COUNTIF(Inventory!$B:$B,$A7) | C7: =SUMIF(Inventory!$B:$B,$A7,Inventory!$S:$S) | D7: =SUMIF(Inventory!$B:$B,$A7,Inventory!$T:$T) | E7: =IFERROR(AVERAGEIF(Inventory!$B:$B,$A7,Inventory!$I:$I),0)
A8: Night Out | B8: =COUNTIF(Inventory!$B:$B,$A8) | C8: =SUMIF(Inventory!$B:$B,$A8,Inventory!$S:$S) | D8: =SUMIF(Inventory!$B:$B,$A8,Inventory!$T:$T) | E8: =IFERROR(AVERAGEIF(Inventory!$B:$B,$A8,Inventory!$I:$I),0)
A9: Vacation | B9: =COUNTIF(Inventory!$B:$B,$A9) | C9: =SUMIF(Inventory!$B:$B,$A9,Inventory!$S:$S) | D9: =SUMIF(Inventory!$B:$B,$A9,Inventory!$T:$T) | E9: =IFERROR(AVERAGEIF(Inventory!$B:$B,$A9,Inventory!$I:$I),0)
A10: Active | B10: =COUNTIF(Inventory!$B:$B,$A10) | C10: =SUMIF(Inventory!$B:$B,$A10,Inventory!$S:$S) | D10: =SUMIF(Inventory!$B:$B,$A10,Inventory!$T:$T) | E10: =IFERROR(AVERAGEIF(Inventory!$B:$B,$A10,Inventory!$I:$I),0)
A11: Seasonal | B11: =COUNTIF(Inventory!$B:$B,$A11) | C11: =SUMIF(Inventory!$B:$B,$A11,Inventory!$S:$S) | D11: =SUMIF(Inventory!$B:$B,$A11,Inventory!$T:$T) | E11: =IFERROR(AVERAGEIF(Inventory!$B:$B,$A11,Inventory!$I:$I),0)
