Workbook
Name BrandList: OFFSET(Lists!$H$2,0,0,COUNTA(Lists!$H:$H)-1,1)
Name CategoryList: OFFSET(Lists!$B$2,0,0,COUNTA(Lists!$B:$B)-1,1)
Name ColorList: OFFSET(Lists!$E$2,0,0,COUNTA(Lists!$E:$E)-1,1)
Name ConditionList: OFFSET(Lists!$C$2,0,0,COUNTA(Lists!$C:$C)-1,1)
Name ItemStatusList: OFFSET(Lists!$F$2,0,0,COUNTA(Lists!$F:$F)-1,1)
Name PurchaseStatusList: OFFSET(Lists!$G$2,0,0,COUNTA(Lists!$G:$G)-1,1)
Name SizeList: OFFSET(Lists!$D$2,0,0,COUNTA(Lists!$D:$D)-1,1)
Name WardrobeList: OFFSET(Lists!$A$2,0,0,COUNTA(Lists!$A:$A)-1,1)

Sheet Start Here
A1: Wardrobe Rental Organizer (Excel)
A3: How to use:
A5: 1) Go to the Lists sheet to add / edit dropdown options (Wardrobes, Categories, Sizes, Colors, etc.).
A6: - The dropdowns update automatically as you add new items to the Lists columns.
A7: 2) Go to Inventory and fill in the blue cells (your inputs). Item IDs are already permanent.
A8: 3) For pictures:
A9: - If your Excel supports the IMAGE() function, paste an image URL into 'Image URL' and the Image column will show it.
A10: - If not, you can insert pictures manually (Insert → Pictures).
A11: 4) Wardrobe View:
A12: - Select a wardrobe in cell B1 and the matching inventory will show automatically.
A13: 5) Finance tracking (simple):
A14: - Enter Times Rented for each item. Total Revenue, Total Cost, Profit, and Break-even Rentals calculate automatically.

Sheet Lists
A1: Wardrobes | B1: Categories | C1: Conditions | D1: Sizes | E1: Colors | F1: Item Status | G1: Purchase Status | H1: Brands
B2: Top | C2: New | D2: XXS | E2: Black | F2: Available | G2: Purchased | H2: Uniqlo
A3: After-Hours Assets | B3: Bottom | C3: Like New | D3: XS | E3: White | F3: Rented | G3: Not purchased | H3: COS
A4: The 203 Collection | B4: Outerwear | C4: Good | D4: S | E4: Gray | F4: Cleaning | G4: Pending purchase | H4: ARKET
A5: The Greenwich Standard | B5: Jacket | C5: Fair | D5: M | E5: Brown | F5: Repair | H5: Everlane
A6: Old Money Staples | B6: Coat | C6: Needs Repair | D6: L | E6: Blue | F6: Retired | H6: J.Crew
A7: PSU 2nd and 3rd quarter | B7: Hoodie | D7: XL | E7: Navy | H7: Banana Republic
A8: Kennebunkport Classics | B8: Sweater | D8: XXL | E8: Green | H8: Club Monaco
A9: The Deacon’s Suitcase move in | B9: T-Shirt | D9: XXXL | E9: Red | H9: Buck Mason
A10: Boulder Winter Elevation | B10: Shirt | D10: One Size | E10: Pink | H10: Taylor Stitch
A11: Buff Winterline | B11: Polo | D11: 00 | E11: Purple | H11: Bonobos
A12: Hoosier Freeze | B12: Dress | D12: 0 | E12: Yellow | H12: Abercrombie & Fitch
A13: Palm Shadow | B13: Suit | D13: 2 | E13: Orange | H13: ASKET
A14: Catalina Bloom | B14: Blazer | D14: 4 | E14: Beige | H14: Zara
A15: Chestnut Season | B15: Set | D15: 6 | E15: Tan | H15: Mango
A16: Scarlet Walk | B16: Activewear | D16: 8 | E16: Cream | H16: H&M
A17: Sixth Street Shift | B17: Loungewear | D17: 10 | E17: Off-White | H17: Express
B18: Sleepwear | D18: 12 | E18: Charcoal | H18: Gap
B19: Shoes | D19: 14 | E19: Chocolate | H19: American Eagle
B20: Sneakers | D20: 16 | E20: Silver | H20: Urban Outfitters
B21: Boots | D21: 18 | E21: Light Blue | H21: PacSun
B22: Loafers | D22: 20 | E22: Royal Blue | H22: lululemon
B23: Dress Shoes | D23: 22 | E23: Teal | H23: Vuori
B24: Sandals | D24: 24 | E24: Turquoise | H24: Rhone
B25: Accessory | D25: 25 | E25: Olive | H25: Alo Yoga
B26: Bag | D26: 26 | E26: Forest Green | H26: Ten Thousand
B27: Belt | D27: 27 | E27: Sage | H27: Tracksmith
B28: Hat | D28: 28 | E28: Mustard | H28: Mack Weldon
B29: Jewelry | D29: 29 | E29: Rust | H29: Gymshark
... B39: Sweatshirt | D39: 42 | E39: Animal Print | H39: Columbia
B40: Fleece Full-Zip | D40: 44 | H40: Huckberry
D41: 46 | H41: Mr Porter
D42: 48 | H42: Johnnie-o
D43: 50 | H43: Taylor ied athlete
D44: 52 | H44: ralph lauren
D45: 54 | H45: eddie bauer
D46: 56 | H46: peter millar
D47: 58 | H47: Rhoback
D48: 60 | H48: Bonobos
D49: 28x30 | H49: Lucky Brand
...

Sheet Inventory
A1: Item ID | B1: Wardrobe Name | C1: Item Name | D1: Category | E1: Image URL | F1: Image | G1: Item Link | H1: Cost of Item ($) | I1: Rental Fee ($) | J1: Condition | K1: Size | L1: Color | M1: Brand | N1: Purchase Status | O1: Status | P1: Date Added | Q1: Extra Costs ($) | R1: Times Rented | S1: Total Revenue ($) | T1: Total Cost ($) | U1: Profit ($) | V1: Break-even Rentals | W1: Notes | X1: Image Filename | Y1: Image Path | Z1: Website Status | AA1: Website Tags
A2: W001 | B2: Work | F2: =IF(E2="","",_xludf.IMAGE(E2)) | R2: 6 | S2: =IF($C2="","",$I2*$R2) | T2: =IF($C2="","",(IF($N2="Purchased",$H2,0)+$Q2)) | U2: =IF($C2="","",$S2-$T2) | V2: =IF(OR($C2="",$I2=0),"",CEILING($T2/$I2,1)) | X2: =IF(C2="","",LOWER(SUBSTITUTE(SUBSTITUTE(C2," ","-"),"'",""))&".jpg") | Y2: =IF(X2="","","/inventory/"&X2) | Z2: =IF(O2="Available","available",IF(OR(O2="Rented",O2="Cleaning",O2="Repair"),"unavailable",IF(O2="Retired","unavailable","")))
A3: W002 | B3: The 203 Collection | C3: Smooth Spacer Classic-Fit Pullover Hoodie | D3: Hoodie | E3: https://images.lululemon.com/is/image/lululemon/LM3FH2S_032493_1?wid=2420&op_usm=0.5,2,10,0&fmt=webp&qlt=80,1&fit=constrain,0&op_sharpen=0&resMode=sharp2&iccEmbed=0&printRes=72 | F3: =IF(E3="","",_xlfn.IMAGE(E3)) | G3: https://shop.lululemon.com/p/mens-jackets-and-hoodies-hoodies/Smooth-Spacer-Classic-Pullover-Hoodie-MD/_/prod11700269?color=32493&locale=en_US&sl=US&sz=L&cid=Google_SHOP_US_NAT_EN_X_BrandShop_Incr-All_OMNI_GEN_Y24_ag-SHOP_G_US_EN_DM_X_GEN_NO_Brand-Core&gclsrc=aw.ds&gad_source=1&gad_campaignid=21471260535&gbraid=0AAAAADL8AvkwNoALWkmcChLEVHdpP_qHJ&gclid=Cj0KCQiAr5nKBhCpARIsACa_NiPUoC6z8tz-beMYzscXuPLZcgjjUeaxbwXxF--wphqJwY5dKj-8xpcaAhTNEALw_wcB | H3: 59 | J3: New | L3: Gray | M3: lululemon | N3: Not purchased | S3: =IF($C3="","",$I3*$R3) | T3: =IF($C3="","",(IF($N3="Purchased",$H3,0)+$Q3)) | U3: =IF($C3="","",$S3-$T3) | V3: =IF(OR($C3="",$I3=0),"",CEILING($T3/$I3,1)) | X3: =IF(C3="","",LOWER(SUBSTITUTE(SUBSTITUTE(C3," ","-"),"'",""))&".jpg") | Y3: =IF(X3="","","/inventory/"&X3) | Z3: =IF(O3="Available","available",IF(OR(O3="Rented",O3="Cleaning",O3="Repair"),"unavailable",IF(O3="Retired","unavailable","")))
A4: W003 | B4: The 203 Collection | C4: Steady State Pullover Hoodie | D4: Hoodie | E4: https://images.lululemon.com/is/image/lululemon/LM3FAES_028022_1?wid=1800&op_usm=0.8,1,10,0&fmt=webp&qlt=80,1&fit=constrain,0&op_sharpen=0&resMode=sharp2&iccEmbed=0&printRes=72 | F4: =IF(E4="","",_xlfn.IMAGE(E4)) | G4: https://shop.lululemon.com/p/mens-jackets-and-hoodies-hoodies/Steady-State-Pullover-Hoodie/_/prod11750325 | H4: 128 | J4: New | N4: Not purchased | S4: =IF($C4="","",$I4*$R4) | T4: =IF($C4="","",(IF($N4="Purchased",$H4,0)+$Q4)) | U4: =IF($C4="","",$S4-$T4) | V4: =IF(OR($C4="",$I4=0),"",CEILING($T4/$I4,1)) | X4: =IF(C4="","",LOWER(SUBSTITUTE(SUBSTITUTE(C4," ","-"),"'",""))&".jpg") | Y4: =IF(X4="","","/inventory/"&X4) | Z4: =IF(O4="Available","available",IF(OR(O4="Rented",O4="Cleaning",O4="Repair"),"unavailable",IF(O4="Retired","unavailable","")))
A5: W004 | B5: The 203 Collection | C5: Seaside Shirt Jacket | D5: Coat | E5: https://cdn.shopify.com/s/files/1/0022/4008/6074/files/V2016HAO_SP26_M_OUTERWEAR_FRONT_3.jpg?v=1764715582&width=1200&height=1500&crop=center | F5: =IF(E5="","",_xlfn.IMAGE(E5)) | G5: https://vuoriclothing.com/products/seaside-sweatpant-acorn-heather?queryId=1ab6588fc6a27903586917678984e0a7&collection=new | H5: 128 | J5: New | L5: Tan | M5: Vuori | N5: Not purchased | O5: Available | S5: =IF($C5="","",$I5*$R5) | T5: =IF($C5="","",(IF($N5="Purchased",$H5,0)+$Q5)) | U5: =IF($C5="","",$S5-$T5) | V5: =IF(OR($C5="",$I5=0),"",CEILING($T5/$I5,1)) | X5: =IF(C5="","",LOWER(SUBSTITUTE(SUBSTITUTE(C5," ","-"),"'",""))&".jpg") | Y5: =IF(X5="","","/inventory/"&X5) | Z5: =IF(O5="Available","available",IF(OR(O5="Rented",O5="Cleaning",O5="Repair"),"unavailable",IF(O5="Retired","unavailable","")))
A6: W005 | B6: The 203 Collection | C6: Seaside Sweatpant - Long | D6: Sweatpants | E6: https://cdn.shopify.com/s/files/1/0022/4008/6074/files/V4007-28HAO_SP26_M_BOTTOMS_SIDE_3.jpg?v=1765391556&width=1200&height=1500&crop=center | F6: =IF(E6="","",_xlfn.IMAGE(E6)) | S6: =IF($C6="","",$I6*$R6) | T6: =IF($C6="","",(IF($N6="Purchased",$H6,0)+$Q6)) | U6: =IF($C6="","",$S6-$T6) | V6: =IF(OR($C6="",$I6=0),"",CEILING($T6/$I6,1)) | X6: =IF(C6="","",LOWER(SUBSTITUTE(SUBSTITUTE(C6," ","-"),"'",""))&".jpg") | Y6: =IF(X6="","","/inventory/"&X6) | Z6: =IF(O6="Available","available",IF(OR(O6="Rented",O6="Cleaning",O6="Repair"),"unavailable",IF(O6="Retired","unavailable","")))
A7: W006 | B7: The 203 Collection | C7: Men’s 1996 Retro Nuptse Jacket | D7: Jacket | E7: https://assets.thenorthface.com/images/t_img/f_auto,h_400,e_unsharp_mask:100,w_344/dpr_2.0/v1754066544/NF0A3C8DGOE-HERO/Mens-1996-Retro-Nuptse-Jacket.png | F7: =IF(E7="","",_xlfn.IMAGE(E7)) | S7: =IF($C7="","",$I7*$R7) | T7: =IF($C7="","",(IF($N7="Purchased",$H7,0)+$Q7)) | U7: =IF($C7="","",$S7-$T7) | V7: =IF(OR($C7="",$I7=0),"",CEILING($T7/$I7,1)) | X7: =IF(C7="","",LOWER(SUBSTITUTE(SUBSTITUTE(C7," ","-"),"'",""))&".jpg") | Y7: =IF(X7="","","/inventory/"&X7) | Z7: =IF(O7="Available","available",IF(OR(O7="Rented",O7="Cleaning",O7="Repair"),"unavailable",IF(O7="Retired","unavailable","")))
A8: W007 | B8: The 203 Collection | C8: Commuter® Pant - Classic | D8: pants | E8: https://cdn.shopify.com/s/files/1/0249/7784/files/CommuterPantClassic-TrueNavy-100161-404_c1_1000x.jpg?v=1736523436&format=webp | F8: =IF(E8="","",_xlfn.IMAGE(E8)) | S8: =IF($C8="","",$I8*$R8) | T8: =IF($C8="","",(IF($N8="Purchased",$H8,0)+$Q8)) | U8: =IF($C8="","",$S8-$T8) | V8: =IF(OR($C8="",$I8=0),"",CEILING($T8/$I8,1)) | X8: =IF(C8="","",LOWER(SUBSTITUTE(SUBSTITUTE(C8," ","-"),"'",""))&".jpg") | Y8: =IF(X8="","","/inventory/"&X8) | Z8: =IF(O8="Available","available",IF(OR(O8="Rented",O8="Cleaning",O8="Repair"),"unavailable",IF(O8="Retired","unavailable","")))
A9: W008 | B9: The 203 Collection | C9: Commuter® 1/4 Zip Sweater | D9: Qzip | E9: https://cdn.shopify.com/s/files/1/0249/7784/files/20240605_Rhone_Boston_CommuterQuarterZip2_1437_1000x.jpg?v=1736523295&format=webp | F9: =IF(E9="","",_xlfn.IMAGE(E9)) | H9: 128 | S9: =IF($C9="","",$I9*$R9) | T9: =IF($C9="","",(IF($N9="Purchased",$H9,0)+$Q9)) | U9: =IF($C9="","",$S9-$T9) | V9: =IF(OR($C9="",$I9=0),"",CEILING($T9/$I9,1)) | X9: =IF(C9="","",LOWER(SUBSTITUTE(SUBSTITUTE(C9," ","-"),"'",""))&".jpg") | Y9: =IF(X9="","","/inventory/"&X9) | Z9: =IF(O9="Available","available",IF(OR(O9="Rented",O9="Cleaning",O9="Repair"),"unavailable",IF(O9="Retired","unavailable","")))
A10: W009 | B10: Old Money Staples | C10: Men’s Arden Cotton-Linen Lapel Shirt | D10: long sleeve buttondown | E10: https://peteroliveira.com/cdn/shop/files/MASTR002-3.jpg?v=1758569250&width=2560 | F10: =IF(E10="","",_xlfn.IMAGE(E10)) | G10: https://peteroliveira.com/products/men-s-arden-cotton-linen-lapel-shirt?variant=51571634176338&tw_source=google&tw_adid=&tw_campaign=23006997322&tw_kwdid=&gad_source=1&gad_campaignid=22996803021&gbraid=0AAAABBTaU6vUB-5ShbwzsU6umzNJDSs6O&gclid=CjwKCAiAmKnKBhBrEiwAaqAnZ0oaQuhX9Jj28DOquPuDEjwQhLIqHeoUotKJNHBH3c0Khhj27OT9exoCBgMQAvD_BwE | S10: =IF($C10="","",$I10*$R10) | T10: =IF($C10="","",(IF($N10="Purchased",$H10,0)+$Q10)) | U10: =IF($C10="","",$S10-$T10) | V10: =IF(OR($C10="",$I10=0),"",CEILING($T10/$I10,1)) | X10: =IF(C10="","",LOWER(SUBSTITUTE(SUBSTITUTE(C10," ","-"),"'",""))&".jpg") | Y10: =IF(X10="","","/inventory/"&X10) | Z10: =IF(O10="Available","available",IF(OR(O10="Rented",O10="Cleaning",O10="Repair"),"unavailable",IF(O10="Retired","unavailable","")))
A11: W010 | B11: Old Money Staples | C11: Linen Blend Cuban Collar Shirt in Stone | D11: long sleeve buttondown | E11: https://tailoredathlete.com/cdn/shop/files/MJV04564_5000x.jpg?v=1745037020 | F11: =IF(E11="","",_xlfn.IMAGE(E11)) | G11: https://tailoredathlete.com/products/linen-blend-cuban-collar-shirt-in-stone?variant=45881600114909&country=US&currency=USD&utm_medium=product_sync&utm_source=google&utm_content=sag_organic&utm_campaign=sag_organic&tw_source=google&tw_adid=&tw_campaign=22715163839&tw_kwdid=&gad_source=1&gad_campaignid=22715165474&gbraid=0AAAAADqbZP8jc4hm7Ps2UbIj3QtqSmML_&gclid=CjwKCAiAmKnKBhBrEiwAaqAnZ-5aLZqkHsTlfAB-DH6lZxaKHo9cevRLaoBLyJwwfty3CgIyz1P_9xoCdOcQAvD_BwE | S11: =IF($C11="","",$I11*$R11) | T11: =IF($C11="","",(IF($N11="Purchased",$H11,0)+$Q11)) | U11: =IF($C11="","",$S11-$T11) | V11: =IF(OR($C11="",$I11=0),"",CEILING($T11/$I11,1)) | X11: =IF(C11="","",LOWER(SUBSTITUTE(SUBSTITUTE(C11," ","-"),"'",""))&".jpg") | Y11: =IF(X11="","","/inventory/"&X11) | Z11: =IF(O11="Available","available",IF(OR(O11="Rented",O11="Cleaning",O11="Repair"),"unavailable",IF(O11="Retired","unavailable","")))
A12: W011 | B12: Old Money Staples | C12: Featherweight Performance Polo - Warwick Stripe | D12: Polo | E12: https://cdn.shopify.com/s/files/1/2275/0137/files/FA25_MENS_OF_WARWICK_JMPO7330_TIDE_008_d6ccedc3-c21a-487b-9f64-676f4150ae28.jpg?v=1765230900&width=1600 | F12: =IF(E12="","",_xlfn.IMAGE(E12)) | S12: =IF($C12="","",$I12*$R12) | T12: =IF($C12="","",(IF($N12="Purchased",$H12,0)+$Q12)) | U12: =IF($C12="","",$S12-$T12) | V12: =IF(OR($C12="",$I12=0),"",CEILING($T12/$I12,1)) | X12: =IF(C12="","",LOWER(SUBSTITUTE(SUBSTITUTE(C12," ","-"),"'",""))&".jpg") | Y12: =IF(X12="","","/inventory/"&X12) | Z12: =IF(O12="Available","available",IF(OR(O12="Rented",O12="Cleaning",O12="Repair"),"unavailable",IF(O12="Retired","unavailable","")))
A13: W012 | B13: Kennebunkport Classics | C13: The Iconic Mesh Polo Shirt | D13: Polo | E13: https://dtcralphlauren.scene7.com/is/image/PoloGSI/s7-AI710534735487_alternate1?$rl_4x5_zoom$ | F13: =IF(E13="","",_xlfn.IMAGE(E13)) | G13: https://www.ralphlauren.com/men-clothing-polo-shirts/the-iconic-mesh-polo-shirt---all-fits/401480-P.html?masterId=401480&userSelectedColor=White%2FNavy&cgid=men-clothing-polo-shirts#start=1&cgid=men-clothing-polo-shirts | H13: 118 | J13: New | K13: M | L13: Red | M13: ralph lauren | N13: Purchased | O13: Available | P13: 46016 | S13: =IF($C13="","",$I13*$R13) | T13: =IF($C13="","",(IF($N13="Purchased",$H13,0)+$Q13)) | U13: =IF($C13="","",$S13-$T13) | V13: =IF(OR($C13="",$I13=0),"",CEILING($T13/$I13,1)) | X13: =IF(C13="","",LOWER(SUBSTITUTE(SUBSTITUTE(C13," ","-"),"'",""))&".jpg") | Y13: =IF(X13="","","/inventory/"&X13) | Z13: =IF(O13="Available","available",IF(OR(O13="Rented",O13="Cleaning",O13="Repair"),"unavailable",IF(O13="Retired","unavailable","")))
A14: W013 | B14: PSU 2nd and 3rd quarter | C14: Men's Faux Shearling-Lined Denim Shirt Jacket | D14: Jacket | E14: https://assets.eddiebauer.com/match/mName/D0340916_488C1/13401910?preset=199 | F14: =IF(E14="","",_xlfn.IMAGE(E14)) | G14: file:///Users/benjamindavenport/Downloads/Men's%20Faux%20Shearling-lined%20Denim%20Shirt%20Jacket%20_%20Eddie%20Bauer.mhtml | H14: 64 | J14: New | M14: edd | S14: =IF($C14="","",$I14*$R14) | T14: =IF($C14="","",(IF($N14="Purchased",$H14,0)+$Q14)) | U14: =IF($C14="","",$S14-$T14) | V14: =IF(OR($C14="",$I14=0),"",CEILING($T14/$I14,1)) | X14: =IF(C14="","",LOWER(SUBSTITUTE(SUBSTITUTE(C14," ","-"),"'",""))&".jpg") | Y14: =IF(X14="","","/inventory/"&X14) | Z14: =IF(O14="Available","available",IF(OR(O14="Rented",O14="Cleaning",O14="Repair"),"unavailable",IF(O14="Retired","unavailable","")))
A15: W014 | B15: The Deacon’s Suitcase move in | C15: Aurora Performance Long-Sleeve T-Shirt | D15: Long Sleeve | E15: https://www.petermillar.com/dw/image/v2/BHFJ_PRD/on/demandware.static/-/Sites-pm-master-catalog/default/dw27e059e8/ME0EK301_BLK_ALT_A.jpg?sw=880&sh=990&fmt=webp | F15: =IF(E15="","",_xlfn.IMAGE(E15)) | G15: https://www.petermillar.com/p/aurora-performance-long-sleeve-t-shirt/me0ek301.html?dwvar_me0ek301_color=BLK | S15: =IF($C15="","",$I15*$R15) | T15: =IF($C15="","",(IF($N15="Purchased",$H15,0)+$Q15)) | U15: =IF($C15="","",$S15-$T15) | V15: =IF(OR($C15="",$I15=0),"",CEILING($T15/$I15,1)) | X15: =IF(C15="","",LOWER(SUBSTITUTE(SUBSTITUTE(C15," ","-"),"'",""))&".jpg") | Y15: =IF(X15="","","/inventory/"&X15) | Z15: =IF(O15="Available","available",IF(OR(O15="Rented",O15="Cleaning",O15="Repair"),"unavailable",IF(O15="Retired","unavailable","")))
A16: W015 | B16: PSU 2nd and 3rd quarter | C16: Summit Fleece Full-Zip | D16: Fleece Full-Zip | E16: https://cdn.shopify.com/s/files/1/1366/9275/files/SOLID_FLEET_NAVY_SUMMIT_FLEECE_FULL-ZIP_MFJA_1.jpg?v=1759861875&width=1800&height=1800&crop=center | F16: =IF(E16="","",_xlfn.IMAGE(E16)) | G16: https://rhoback.com/products/mens-tops-summit-fleece-full-zip-solid-fleet-navy?Color=Fleet+Navy&Size=S | S16: =IF($C16="","",$I16*$R16) | T16: =IF($C16="","",(IF($N16="Purchased",$H16,0)+$Q16)) | U16: =IF($C16="","",$S16-$T16) | V16: =IF(OR($C16="",$I16=0),"",CEILING($T16/$I16,1)) | X16: =IF(C16="","",LOWER(SUBSTITUTE(SUBSTITUTE(C16," ","-"),"'",""))&".jpg") | Y16: =IF(X16="","","/inventory/"&X16) | Z16: =IF(O16="Available","available",IF(OR(O16="Rented",O16="Cleaning",O16="Repair"),"unavailable",IF(O16="Retired","unavailable","")))
A17: W016 | F17: =IF(E17="","",_xlfn.IMAGE(E17)) | S17: =IF($C17="","",$I17*$R17) | T17: =IF($C17="","",(IF($N17="Purchased",$H17,0)+$Q17)) | U17: =IF($C17="","",$S17-$T17) | V17: =IF(OR($C17="",$I17=0),"",CEILING($T17/$I17,1)) | X17: =IF(C17="","",LOWER(SUBSTITUTE(SUBSTITUTE(C17," ","-"),"'",""))&".jpg") | Y17: =IF(X17="","","/inventory/"&X17) | Z17: =IF(O17="Available","available",IF(OR(O17="Rented",O17="Cleaning",O17="Repair"),"unavailable",IF(O17="Retired","unavailable","")))
A18: W017 | F18: =IF(E18="","",_xlfn.IMAGE(E18)) | S18: =IF($C18="","",$I18*$R18) | T18: =IF($C18="","",(IF($N18="Purchased",$H18,0)+$Q18)) | U18: =IF($C18="","",$S18-$T18) | V18: =IF(OR($C18="",$I18=0),"",CEILING($T18/$I18,1)) | X18: =IF(C18="","",LOWER(SUBSTITUTE(SUBSTITUTE(C18," ","-"),"'",""))&".jpg") | Y18: =IF(X18="","","/inventory/"&X18) | Z18: =IF(O18="Available","available",IF(OR(O18="Rented",O18="Cleaning",O18="Repair"),"unavailable",IF(O18="Retired","unavailable","")))
A19: W018 | F19: =IF(E19="","",_xlfn.IMAGE(E19)) | S19: =IF($C19="","",$I19*$R19) | T19: =IF($C19="","",(IF($N19="Purchased",$H19,0)+$Q19)) | U19: =IF($C19="","",$S19-$T19) | V19: =IF(OR($C19="",$I19=0),"",CEILING($T19/$I19,1)) | X19: =IF(C19="","",LOWER(SUBSTITUTE(SUBSTITUTE(C19," ","-"),"'",""))&".jpg") | Y19: =IF(X19="","","/inventory/"&X19) | Z19: =IF(O19="Available","available",IF(OR(O19="Rented",O19="Cleaning",O19="Repair"),"unavailable",IF(O19="Retired","unavailable","")))
A20: W019 | F20: =IF(E20="","",_xlfn.IMAGE(E20)) | S20: =IF($C20="","",$I20*$R20) | T20: =IF($C20="","",(IF($N20="Purchased",$H20,0)+$Q20)) | U20: =IF($C20="","",$S20-$T20) | V20: =IF(OR($C20="",$I20=0),"",CEILING($T20/$I20,1)) | X20: =IF(C20="","",LOWER(SUBSTITUTE(SUBSTITUTE(C20," ","-"),"'",""))&".jpg") | Y20: =IF(X20="","","/inventory/"&X20) | Z20: =IF(O20="Available","available",IF(OR(O20="Rented",O20="Cleaning",O20="Repair"),"unavailable",IF(O20="Retired","unavailable","")))
A21: W020 | F21: =IF(E21="","",_xlfn.IMAGE(E21)) | S21: =IF($C21="","",$I21*$R21) | T21: =IF($C21="","",(IF($N21="Purchased",$H21,0)+$Q21)) | U21: =IF($C21="","",$S21-$T21) | V21: =IF(OR($C21="",$I21=0),"",CEILING($T21/$I21,1)) | X21: =IF(C21="","",LOWER(SUBSTITUTE(SUBSTITUTE(C21," ","-"),"'",""))&".jpg") | Y21: =IF(X21="","","/inventory/"&X21) | Z21: =IF(O21="Available","available",IF(OR(O21="Rented",O21="Cleaning",O21="Repair"),"unavailable",IF(O21="Retired","unavailable","")))
A22: W021 | F22: =IF(E22="","",_xlfn.IMAGE(E22)) | S22: =IF($C22="","",$I22*$R22) | T22: =IF($C22="","",(IF($N22="Purchased",$H22,0)+$Q22)) | U22: =IF($C22="","",$S22-$T22) | V22: =IF(OR($C22="",$I22=0),"",CEILING($T22/$I22,1)) | X22: =IF(C22="","",LOWER(SUBSTITUTE(SUBSTITUTE(C22," ","-"),"'",""))&".jpg") | Y22: =IF(X22="","","/inventory/"&X22) | Z22: =IF(O22="Available","available",IF(OR(O22="Rented",O22="Cleaning",O22="Repair"),"unavailable",IF(O22="Retired","unavailable","")))
A23: W022 | F23: =IF(E23="","",_xlfn.IMAGE(E23)) | S23: =IF($C23="","",$I23*$R23) | T23: =IF($C23="","",(IF($N23="Purchased",$H23,0)+$Q23)) | U23: =IF($C23="","",$S23-$T23) | V23: =IF(OR($C23="",$I23=0),"",CEILING($T23/$I23,1)) | X23: =IF(C23="","",LOWER(SUBSTITUTE(SUBSTITUTE(C23," ","-"),"'",""))&".jpg") | Y23: =IF(X23="","","/inventory/"&X23) | Z23: =IF(O23="Available","available",IF(OR(O23="Rented",O23="Cleaning",O23="Repair"),"unavailable",IF(O23="Retired","unavailable","")))
A24: W023 | F24: =IF(E24="","",_xlfn.IMAGE(E24)) | S24: =IF($C24="","",$I24*$R24) | T24: =IF($C24="","",(IF($N24="Purchased",$H24,0)+$Q24)) | U24: =IF($C24="","",$S24-$T24) | V24: =IF(OR($C24="",$I24=0),"",CEILING($T24/$I24,1)) | X24: =IF(C24="","",LOWER(SUBSTITUTE(SUBSTITUTE(C24," ","-"),"'",""))&".jpg") | Y24: =IF(X24="","","/inventory/"&X24) | Z24: =IF(O24="Available","available",IF(OR(O24="Rented",O24="Cleaning",O24="Repair"),"unavailable",IF(O24="Retired","unavailable","")))
A25: W024 | F25: =IF(E25="","",_xlfn.IMAGE(E25)) | S25: =IF($C25="","",$I25*$R25) | T25: =IF($C25="","",(IF($N25="Purchased",$H25,0)+$Q25)) | U25: =IF($C25="","",$S25-$T25) | V25: =IF(OR($C25="",$I25=0),"",CEILING($T25/$I25,1)) | X25: =IF(C25="","",LOWER(SUBSTITUTE(SUBSTITUTE(C25," ","-"),"'",""))&".jpg") | Y25: =IF(X25="","","/inventory/"&X25) | Z25: =IF(O25="Available","available",IF(OR(O25="Rented",O25="Cleaning",O25="Repair"),"unavailable",IF(O25="Retired","unavailable","")))
A26: W025 | F26: =IF(E26="","",_xlfn.IMAGE(E26)) | S26: =IF($C26="","",$I26*$R26) | T26: =IF($C26="","",(IF($N26="Purchased",$H26,0)+$Q26)) | U26: =IF($C26="","",$S26-$T26) | V26: =IF(OR($C26="",$I26=0),"",CEILING($T26/$I26,1)) | X26: =IF(C26="","",LOWER(SUBSTITUTE(SUBSTITUTE(C26," ","-"),"'",""))&".jpg") | Y26: =IF(X26="","","/inventory/"&X26) | Z26: =IF(O26="Available","available",IF(OR(O26="Rented",O26="Cleaning",O26="Repair"),"unavailable",IF(O26="Retired","unavailable","")))
A27: W026 | F27: =IF(E27="","",_xlfn.IMAGE(E27)) | S27: =IF($C27="","",$I27*$R27) | T27: =IF($C27="","",(IF($N27="Purchased",$H27,0)+$Q27)) | U27: =IF($C27="","",$S27-$T27) | V27: =IF(OR($C27="",$I27=0),"",CEILING($T27/$I27,1)) | X27: =IF(C27="","",LOWER(SUBSTITUTE(SUBSTITUTE(C27," ","-"),"'",""))&".jpg") | Y27: =IF(X27="","","/inventory/"&X27) | Z27: =IF(O27="Available","available",IF(OR(O27="Rented",O27="Cleaning",O27="Repair"),"unavailable",IF(O27="Retired","unavailable","")))
A28: W027 | F28: =IF(E28="","",_xlfn.IMAGE(E28)) | S28: =IF($C28="","",$I28*$R28) | T28: =IF($C28="","",(IF($N28="Purchased",$H28,0)+$Q28)) | U28: =IF($C28="","",$S28-$T28) | V28: =IF(OR($C28="",$I28=0),"",CEILING($T28/$I28,1)) | X28: =IF(C28="","",LOWER(SUBSTITUTE(SUBSTITUTE(C28," ","-"),"'",""))&".jpg") | Y28: =IF(X28="","","/inventory/"&X28) | Z28: =IF(O28="Available","available",IF(OR(O28="Rented",O28="Cleaning",O28="Repair"),"unavailable",IF(O28="Retired","unavailable","")))
... A500: W499 | F500: =IF(E500="","",_xlfn.IMAGE(E500)) | S500: =IF($C500="","",$I500*$R500) | T500: =IF($C500="","",(IF($N500="Purchased",$H500,0)+$Q500)) | U500: =IF($C500="","",$S500-$T500) | V500: =IF(OR($C500="",$I500=0),"",CEILING($T500/$I500,1)) | X500: =IF(C500="","",LOWER(SUBSTITUTE(SUBSTITUTE(C500," ","-"),"'",""))&".jpg") | Y500: =IF(X500="","","/inventory/"&X500) | Z500: =IF(O500="Available","available",IF(OR(O500="Rented",O500="Cleaning",O500="Repair"),"unavailable",IF(O500="Retired","unavailable","")))

Sheet Website_Inventory
A1: id | B1: wardrobe | C1: name | D1: category | E1: sizes | F1: price | G1: status | H1: image | I1: notes | J1: tags
A2: =IF(Inventory!A2="","",Inventory!A2) | B2: =IF(Inventory!A2="","",Inventory!B2) | C2: =IF(Inventory!A2="","",Inventory!C2) | D2: =IF(Inventory!A2="","",Inventory!D2) | E2: =IF(Inventory!A2="","",Inventory!K2) | F2: =IF(Inventory!A2="","",Inventory!I2) | G2: =IF(Inventory!A2="","",Inventory!Z2) | H2: =IF(Inventory!A2="","",Inventory!Y2) | I2: =IF(Inventory!A2="","",Inventory!W2) | J2: =IF(Inventory!A2="","",Inventory!AA2)
A3: =IF(Inventory!A3="","",Inventory!A3) | B3: =IF(Inventory!A3="","",Inventory!B3) | C3: =IF(Inventory!A3="","",Inventory!C3) | D3: =IF(Inventory!A3="","",Inventory!D3) | E3: =IF(Inventory!A3="","",Inventory!K3) | F3: =IF(Inventory!A3="","",Inventory!I3) | G3: =IF(Inventory!A3="","",Inventory!Z3) | H3: =IF(Inventory!A3="","",Inventory!Y3) | I3: =IF(Inventory!A3="","",Inventory!W3) | J3: =IF(Inventory!A3="","",Inventory!AA3)
A4: =IF(Inventory!A4="","",Inventory!A4) | B4: =IF(Inventory!A4="","",Inventory!B4) | C4: =IF(Inventory!A4="","",Inventory!C4) | D4: =IF(Inventory!A4="","",Inventory!D4) | E4: =IF(Inventory!A4="","",Inventory!K4) | F4: =IF(Inventory!A4="","",Inventory!I4) | G4: =IF(Inventory!A4="","",Inventory!Z4) | H4: =IF(Inventory!A4="","",Inventory!Y4) | I4: =IF(Inventory!A4="","",Inventory!W4) | J4: =IF(Inventory!A4="","",Inventory!AA4)
A5: =IF(Inventory!A5="","",Inventory!A5) | B5: =IF(Inventory!A5="","",Inventory!B5) | C5: =IF(Inventory!A5="","",Inventory!C5) | D5: =IF(Inventory!A5="","",Inventory!D5) | E5: =IF(Inventory!A5="","",Inventory!K5) | F5: =IF(Inventory!A5="","",Inventory!I5) | G5: =IF(Inventory!A5="","",Inventory!Z5) | H5: =IF(Inventory!A5="","",Inventory!Y5) | I5: =IF(Inventory!A5="","",Inventory!W5) | J5: =IF(Inventory!A5="","",Inventory!AA5)
A6: =IF(Inventory!A6="","",Inventory!A6) | B6: =IF(Inventory!A6="","",Inventory!B6) | C6: =IF(Inventory!A6="","",Inventory!C6) | D6: =IF(Inventory!A6="","",Inventory!D6) | E6: =IF(Inventory!A6="","",Inventory!K6) | F6: =IF(Inventory!A6="","",Inventory!I6) | G6: =IF(Inventory!A6="","",Inventory!Z6) | H6: =IF(Inventory!A6="","",Inventory!Y6) | I6: =IF(Inventory!A6="","",Inventory!W6) | J6: =IF(Inventory!A6="","",Inventory!AA6)
A7: =IF(Inventory!A7="","",Inventory!A7) | B7: =IF(Inventory!A7="","",Inventory!B7) | C7: =IF(Inventory!A7="","",Inventory!C7) | D7: =IF(Inventory!A7="","",Inventory!D7) | E7: =IF(Inventory!A7="","",Inventory!K7) | F7: =IF(Inventory!A7="","",Inventory!I7) | G7: =IF(Inventory!A7="","",Inventory!Z7) | H7: =IF(Inventory!A7="","",Inventory!Y7) | I7: =IF(Inventory!A7="","",Inventory!W7) | J7: =IF(Inventory!A7="","",Inventory!AA7)
A8: =IF(Inventory!A8="","",Inventory!A8) | B8: =IF(Inventory!A8="","",Inventory!B8) | C8: =IF(Inventory!A8="","",Inventory!C8) | D8: =IF(Inventory!A8="","",Inventory!D8) | E8: =IF(Inventory!A8="","",Inventory!K8) | F8: =IF(Inventory!A8="","",Inventory!I8) | G8: =IF(Inventory!A8="","",Inventory!Z8) | H8: =IF(Inventory!A8="","",Inventory!Y8) | I8: =IF(Inventory!A8="","",Inventory!W8) | J8: =IF(Inventory!A8="","",Inventory!AA8)
A9: =IF(Inventory!A9="","",Inventory!A9) | B9: =IF(Inventory!A9="","",Inventory!B9) | C9: =IF(Inventory!A9="","",Inventory!C9) | D9: =IF(Inventory!A9="","",Inventory!D9) | E9: =IF(Inventory!A9="","",Inventory!K9) | F9: =IF(Inventory!A9="","",Inventory!I9) | G9: =IF(Inventory!A9="","",Inventory!Z9) | H9: =IF(Inventory!A9="","",Inventory!Y9) | I9: =IF(Inventory!A9="","",Inventory!W9) | J9: =IF(Inventory!A9="","",Inventory!AA9)
A10: =IF(Inventory!A10="","",Inventory!A10) | B10: =IF(Inventory!A10="","",Inventory!B10) | C10: =IF(Inventory!A10="","",Inventory!C10) | D10: =IF(Inventory!A10="","",Inventory!D10) | E10: =IF(Inventory!A10="","",Inventory!K10) | F10: =IF(Inventory!A10="","",Inventory!I10) | G10: =IF(Inventory!A10="","",Inventory!Z10) | H10: =IF(Inventory!A10="","",Inventory!Y10) | I10: =IF(Inventory!A10="","",Inventory!W10) | J10: =IF(Inventory!A10="","",Inventory!AA10)
A11: =IF(Inventory!A11="","",Inventory!A11) | B11: =IF(Inventory!A11="","",Inventory!B11) | C11: =IF(Inventory!A11="","",Inventory!C11) | D11: =IF(Inventory!A11="","",Inventory!D11) | E11: =IF(Inventory!A11="","",Inventory!K11) | F11: =IF(Inventory!A11="","",Inventory!I11) | G11: =IF(Inventory!A11="","",Inventory!Z11) | H11: =IF(Inventory!A11="","",Inventory!Y11) | I11: =IF(Inventory!A11="","",Inventory!W11) | J11: =IF(Inventory!A11="","",Inventory!AA11)
A12: =IF(Inventory!A12="","",Inventory!A12) | B12: =IF(Inventory!A12="","",Inventory!B12) | C12: =IF(Inventory!A12="","",Inventory!C12) | D12: =IF(Inventory!A12="","",Inventory!D12) | E12: =IF(Inventory!A12="","",Inventory!K12) | F12: =IF(Inventory!A12="","",Inventory!I12) | G12: =IF(Inventory!A12="","",Inventory!Z12) | H12: =IF(Inventory!A12="","",Inventory!Y12) | I12: =IF(Inventory!A12="","",Inventory!W12) | J12: =IF(Inventory!A12="","",Inventory!AA12)
A13: =IF(Inventory!A13="","",Inventory!A13) | B13: =IF(Inventory!A13="","",Inventory!B13) | C13: =IF(Inventory!A13="","",Inventory!C13) | D13: =IF(Inventory!A13="","",Inventory!D13) | E13: =IF(Inventory!A13="","",Inventory!K13) | F13: =IF(Inventory!A13="","",Inventory!I13) | G13: =IF(Inventory!A13="","",Inventory!Z13) | H13: =IF(Inventory!A13="","",Inventory!Y13) | I13: =IF(Inventory!A13="","",Inventory!W13) | J13: =IF(Inventory!A13="","",Inventory!AA13)
... A500: =IF(Inventory!A500="","",Inventory!A500) | B500: =IF(Inventory!A500="","",Inventory!B500) | C500: =IF(Inventory!A500="","",Inventory!C500) | D500: =IF(Inventory!A500="","",Inventory!D500) | E500: =IF(Inventory!A500="","",Inventory!K500) | F500: =IF(Inventory!A500="","",Inventory!I500) | G500: =IF(Inventory!A500="","",Inventory!Z500) | H500: =IF(Inventory!A500="","",Inventory!Y500) | I500: =IF(Inventory!A500="","",Inventory!W500) | J500: =IF(Inventory!A500="","",Inventory!AA500)

Sheet Wardrobe View
A1: Select wardrobe: | B1: PSU 2nd and 3rd quarter
A3: Matching items (auto):
A5: Item ID | B5: Wardrobe Name | C5: Item Name | D5: Category | E5: Image URL | F5: Image | G5: Item Link | H5: Cost of Item ($) | I5: Rental Fee ($) | J5: Condition | K5: Size | L5: Color | M5: Brand | N5: Purchase Status | O5: Status | P5: Date Added | Q5: Extra Costs ($) | R5: Times Rented | S5: Total Revenue ($) | T5: Total Cost ($) | U5: Profit ($) | V5: Break-even Rentals | W5: Notes
A6: {=IF($B$1="","",_xlfn._xlws.FILTER(Inventory!A2:W2000,Inventory!B2:B2000=$B$1,"No matches"))}

Sheet Dashboard
A1: Dashboard
A2: Tip: Add items in Inventory. Dashboard updates automatically. | G2: Total Items | H2: =COUNTIF(Inventory!A:A,"<>")-1
A3: Wardrobe | B3: # Items | C3: Total Revenue ($) | D3: Total Profit ($) | E3: Avg Rental Fee ($) | G3: Total Revenue | H3: =SUM(Inventory!S:S)
A4: =IF(Lists!A2="","",Lists!A2) | B4: =IF($A4="","",COUNTIF(Inventory!B:B,$A4)) | C4: =IF($A4="","",SUMIF(Inventory!B:B,$A4,Inventory!S:S)) | D4: =IF($A4="","",SUMIF(Inventory!B:B,$A4,Inventory!U:U)) | E4: =IF($A4="","",AVERAGEIF(Inventory!B:B,$A4,Inventory!I:I)) | G4: Total Profit | H4: =SUM(Inventory!U:U)
A5: =IF(Lists!A3="","",Lists!A3) | B5: =IF($A5="","",COUNTIF(Inventory!B:B,$A5)) | C5: =IF($A5="","",SUMIF(Inventory!B:B,$A5,Inventory!S:S)) | D5: =IF($A5="","",SUMIF(Inventory!B:B,$A5,Inventory!U:U)) | E5: =IF($A5="","",AVERAGEIF(Inventory!B:B,$A5,Inventory!I:I)) | G5: Avg Rental Fee | H5: =AVERAGEIF(Inventory!I:I,">0",Inventory!I:I)
A6: =IF(Lists!A4="","",Lists!A4) | B6: =IF($A6="","",COUNTIF(Inventory!B:B,$A6)) | C6: =IF($A6="","",SUMIF(Inventory!B:B,$A6,Inventory!S:S)) | D6: =IF($A6="","",SUMIF(Inventory!B:B,$A6,Inventory!U:U)) | E6: =IF($A6="","",AVERAGEIF(Inventory!B:B,$A6,Inventory!I:I))
A7: =IF(Lists!A5="","",Lists!A5) | B7: =IF($A7="","",COUNTIF(Inventory!B:B,$A7)) | C7: =IF($A7="","",SUMIF(Inventory!B:B,$A7,Inventory!S:S)) | D7: =IF($A7="","",SUMIF(Inventory!B:B,$A7,Inventory!U:U)) | E7: =IF($A7="","",AVERAGEIF(Inventory!B:B,$A7,Inventory!I:I))
A8: =IF(Lists!A6="","",Lists!A6) | B8: =IF($A8="","",COUNTIF(Inventory!B:B,$A8)) | C8: =IF($A8="","",SUMIF(Inventory!B:B,$A8,Inventory!S:S)) | D8: =IF($A8="","",SUMIF(Inventory!B:B,$A8,Inventory!U:U)) | E8: =IF($A8="","",AVERAGEIF(Inventory!B:B,$A8,Inventory!I:I))
A9: =IF(Lists!A7="","",Lists!A7) | B9: =IF($A9="","",COUNTIF(Inventory!B:B,$A9)) | C9: =IF($A9="","",SUMIF(Inventory!B:B,$A9,Inventory!S:S)) | D9: =IF($A9="","",SUMIF(Inventory!B:B,$A9,Inventory!U:U)) | E9: =IF($A9="","",AVERAGEIF(Inventory!B:B,$A9,Inventory!I:I))
A10: =IF(Lists!A8="","",Lists!A8) | B10: =IF($A10="","",COUNTIF(Inventory!B:B,$A10)) | C10: =IF($A10="","",SUMIF(Inventory!B:B,$A10,Inventory!S:S)) | D10: =IF($A10="","",SUMIF(Inventory!B:B,$A10,Inventory!U:U)) | E10: =IF($A10="","",AVERAGEIF(Inventory!B:B,$A10,Inventory!I:I))
A11: =IF(Lists!A9="","",Lists!A9) | B11: =IF($A11="","",COUNTIF(Inventory!B:B,$A11)) | C11: =IF($A11="","",SUMIF(Inventory!B:B,$A11,Inventory!S:S)) | D11: =IF($A11="","",SUMIF(Inventory!B:B,$A11,Inventory!U:U)) | E11: =IF($A11="","",AVERAGEIF(Inventory!B:B,$A11,Inventory!I:I))
A12: =IF(Lists!A10="","",Lists!A10) | B12: =IF($A12="","",COUNTIF(Inventory!B:B,$A12)) | C12: =IF($A12="","",SUMIF(Inventory!B:B,$A12,Inventory!S:S)) | D12: =IF($A12="","",SUMIF(Inventory!B:B,$A12,Inventory!U:U)) | E12: =IF($A12="","",AVERAGEIF(Inventory!B:B,$A12,Inventory!I:I))
A13: =IF(Lists!A11="","",Lists!A11) | B13: =IF($A13="","",COUNTIF(Inventory!B:B,$A13)) | C13: =IF($A13="","",SUMIF(Inventory!B:B,$A13,Inventory!S:S)) | D13: =IF($A13="","",SUMIF(Inventory!B:B,$A13,Inventory!U:U)) | E13: =IF($A13="","",AVERAGEIF(Inventory!B:B,$A13,Inventory!I:I))
A14: =IF(Lists!A12="","",Lists!A12) | B14: =IF($A14="","",COUNTIF(Inventory!B:B,$A14)) | C14: =IF($A14="","",SUMIF(Inventory!B:B,$A14,Inventory!S:S)) | D14: =IF($A14="","",SUMIF(Inventory!B:B,$A14,Inventory!U:U)) | E14: =IF($A14="","",AVERAGEIF(Inventory!B:B,$A14,Inventory!I:I))
A15: =IF(Lists!A13="","",Lists!A13) | B15: =IF($A15="","",COUNTIF(Inventory!B:B,$A15)) | C15: =IF($A15="","",SUMIF(Inventory!B:B,$A15,Inventory!S:S)) | D15: =IF($A15="","",SUMIF(Inventory!B:B,$A15,Inventory!U:U)) | E15: =IF($A15="","",AVERAGEIF(Inventory!B:B,$A15,Inventory!I:I))
A16: =IF(Lists!A14="","",Lists!A14) | B16: =IF($A16="","",COUNTIF(Inventory!B:B,$A16)) | C16: =IF($A16="","",SUMIF(Inventory!B:B,$A16,Inventory!S:S)) | D16: =IF($A16="","",SUMIF(Inventory!B:B,$A16,Inventory!U:U)) | E16: =IF($A16="","",AVERAGEIF(Inventory!B:B,$A16,Inventory!I:I))
A17: =IF(Lists!A15="","",Lists!A15) | B17: =IF($A17="","",COUNTIF(Inventory!B:B,$A17)) | C17: =IF($A17="","",SUMIF(Inventory!B:B,$A17,Inventory!S:S)) | D17: =IF($A17="","",SUMIF(Inventory!B:B,$A17,Inventory!U:U)) | E17: =IF($A17="","",AVERAGEIF(Inventory!B:B,$A17,Inventory!I:I))
... A33: =IF(Lists!A31="","",Lists!A31) | B33: =IF($A33="","",COUNTIF(Inventory!B:B,$A33)) | C33: =IF($A33="","",SUMIF(Inventory!B:B,$A33,Inventory!S:S)) | D33: =IF($A33="","",SUMIF(Inventory!B:B,$A33,Inventory!U:U)) | E33: =IF($A33="","",AVERAGEIF(Inventory!B:B,$A33,Inventory!I:I))

Sheet Sheet2
A1: Wardrobes | B1: Descroptions
A2: Everyday
A3: Work
A4: Casual
A5: Formal
A6: Night Out
A7: Vacation
A8: Active
A9: Seasonal
A10: The 203 Collection | B10: The 203 collection is made for casual style in the summer. Where weeks consist of a casual job along with spending time with friends. This style is curated for a beachy feel with some high end with a mix of stylish normal cllothes. The 203 is named after fairfield county CT area code so you will definitly see some people lookin like you with the wardrobe
A11: The Greenwich Standard
A12: Purely Nantucket
A13: test
