Workbook
Name WardrobeList: OFFSET(Lists!$A$2,0,0,COUNTA(Lists!$A:$A)-1,1)
Name CategoryList: OFFSET(Lists!$B$2,0,0,COUNTA(Lists!$B:$B)-1,1)
Name ConditionList: OFFSET(Lists!$C$2,0,0,COUNTA(Lists!$C:$C)-1,1)
Name SizeList: OFFSET(Lists!$D$2,0,0,COUNTA(Lists!$D:$D)-1,1)
Name ColorList: OFFSET(Lists!$E$2,0,0,COUNTA(Lists!$E:$E)-1,1)
Name ItemStatusList: OFFSET(Lists!$F$2,0,0,COUNTA(Lists!$F:$F)-1,1)
Name PurchaseStatusList: OFFSET(Lists!$G$2,0,0,COUNTA(Lists!$G:$G)-1,1)

Sheet Start Here
A1: Wardrobe Rental Organizer (Excel)
A3: How to use:
A5: 1) Go to the Lists sheet to add / edit dropdown options (Wardrobes, Categories, Sizes, Colors, etc.).
A6: - The dropdowns update automatically as you add new items to the Lists columns.
A7: 2) Go to Inventory and fill in the blue cells (your inputs). Item IDs are already permanent.
A8: 3) For pictures:
A9: - If your Excel supports the IMAGE() function, paste an image URL into 'Image URL' and the Image column will show it.
A10: - If not, you can insert pictures manually (Insert → Pictures).
A11: 4) Wardrobe View:
A12: - Select a wardrobe in cell B1 and the matching inventory will show automatically.
A13: 5) Finance tracking (simple):
A14: - Enter Times Rented for each item. Total Revenue, Total Cost, Profit, and Break-even Rentals calculate automatically.

Sheet Lists
A1: Wardrobes | B1: Categories | C1: Conditions | D1: Sizes | E1: Colors | F1: Item Status | G1: Purchase Status
A2: Everyday | B2: Top | C2: New | D2: XXS | E2: Black | F2: Available | G2: Purchased
A3: Work | B3: Bottom | C3: Like New | D3: XS | E3: White | F3: Rented | G3: Not purchased
A4: Casual | B4: Outerwear | C4: Good | D4: S | E4: Gray | F4: Cleaning | G4: Pending purchase
A5: Formal | B5: Jacket | C5: Fair | D5: M | E5: Brown | F5: Repair
A6: Night Out | B6: Coat | C6: Needs Repair | D6: L | E6: Blue | F6: Retired
A7: Vacation | B7: Hoodie | D7: XL | E7: Navy
A8: Active | B8: Sweater | D8: XXL | E8: Green
A9: Seasonal | B9: T-Shirt | D9: XXXL | E9: Red
B10: Shirt | D10: One Size | E10: Pink
B11: Polo | D11: 00 | E11: Purple
B12: Dress | D12: 0 | E12: Yellow
B13: Suit | D13: 2 | E13: Orange
B14: Blazer | D14: 4 | E14: Beige
B15: Set | D15: 6 | E15: Tan
B16: Activewear | D16: 8 | E16: Cream
B17: Loungewear | D17: 10 | E17: Off-White
B18: Sleepwear | D18: 12 | E18: Charcoal
B19: Shoes | D19: 14 | E19: Chocolate
B20: Sneakers | D20: 16 | E20: Silver
B21: Boots | D21: 18 | E21: Light Blue
... B33: Tie | D33: 33 | E33: Hot Pink
D34: 34 | E34: Lavender
D35: 35 | E35: Gold
D36: 36 | E36: Multicolor
D37: 38 | E37: Patterned
D38: 40 | E38: Denim
D39: 42 | E39: Animal Print
D40: 44
D41: 46
D42: 48
D43: 50
D44: 52
D45: 54
D46: 56
D47: 58
D48: 60
D49: 28x30
D50: 28x32
D51: 30x30
...

Sheet Inventory
A1: Item ID | B1: Wardrobe Name | C1: Item Name | D1: Category | E1: Image URL | F1: Image | G1: Item Link | H1: Cost of Item ($) | I1: Rental Fee ($) | J1: Condition | K1: Size | L1: Color | M1: Brand | N1: Purchase Status | O1: Status | P1: Date Added | Q1: Extra Costs ($) | R1: Times Rented | S1: Total Revenue ($) | T1: Total Cost ($) | U1: Profit ($) | V1: Break-even Rentals | W1: Notes
A2: W001 | B2: Work | C2: Black Blazer | D2: Jacket | F2: =IF(E2="","",IMAGE(E2)) | H2: 120 | I2: 25 | J2: Like New | K2: M | L2: Black | M2: Zara | N2: Purchased | O2: Available | P2: 46012 | Q2: 0 | R2: 6 | S2: =IF($C2="","",$I2*$R2) | T2: =IF($C2="","",(IF($N2="Purchased",$H2,0)+$Q2)) | U2: =IF($C2="","",$S2-$T2) | V2: =IF(OR($C2="",$I2=0),"",CEILING($T2/$I2,1))
A3: W002 | F3: =IF(E3="","",IMAGE(E3)) | S3: =IF($C3="","",$I3*$R3) | T3: =IF($C3="","",(IF($N3="Purchased",$H3,0)+$Q3)) | U3: =IF($C3="","",$S3-$T3) | V3: =IF(OR($C3="",$I3=0),"",CEILING($T3/$I3,1))
A4: W003 | F4: =IF(E4="","",IMAGE(E4)) | S4: =IF($C4="","",$I4*$R4) | T4: =IF($C4="","",(IF($N4="Purchased",$H4,0)+$Q4)) | U4: =IF($C4="","",$S4-$T4) | V4: =IF(OR($C4="",$I4=0),"",CEILING($T4/$I4,1))
A5: W004 | F5: =IF(E5="","",IMAGE(E5)) | S5: =IF($C5="","",$I5*$R5) | T5: =IF($C5="","",(IF($N5="Purchased",$H5,0)+$Q5)) | U5: =IF($C5="","",$S5-$T5) | V5: =IF(OR($C5="",$I5=0),"",CEILING($T5/$I5,1))
A6: W005 | F6: =IF(E6="","",IMAGE(E6)) | S6: =IF($C6="","",$I6*$R6) | T6: =IF($C6="","",(IF($N6="Purchased",$H6,0)+$Q6)) | U6: =IF($C6="","",$S6-$T6) | V6: =IF(OR($C6="",$I6=0),"",CEILING($T6/$I6,1))
A7: W006 | F7: =IF(E7="","",IMAGE(E7)) | S7: =IF($C7="","",$I7*$R7) | T7: =IF($C7="","",(IF($N7="Purchased",$H7,0)+$Q7)) | U7: =IF($C7="","",$S7-$T7) | V7: =IF(OR($C7="",$I7=0),"",CEILING($T7/$I7,1))
A8: W007 | F8: =IF(E8="","",IMAGE(E8)) | S8: =IF($C8="","",$I8*$R8) | T8: =IF($C8="","",(IF($N8="Purchased",$H8,0)+$Q8)) | U8: =IF($C8="","",$S8-$T8) | V8: =IF(OR($C8="",$I8=0),"",CEILING($T8/$I8,1))
A9: W008 | F9: =IF(E9="","",IMAGE(E9)) | S9: =IF($C9="","",$I9*$R9) | T9: =IF($C9="","",(IF($N9="Purchased",$H9,0)+$Q9)) | U9: =IF($C9="","",$S9-$T9) | V9: =IF(OR($C9="",$I9=0),"",CEILING($T9/$I9,1))
A10: W009 | F10: =IF(E10="","",IMAGE(E10)) | S10: =IF($C10="","",$I10*$R10) | T10: =IF($C10="","",(IF($N10="Purchased",$H10,0)+$Q10)) | U10: =IF($C10="","",$S10-$T10) | V10: =IF(OR($C10="",$I10=0),"",CEILING($T10/$I10,1))
A11: W010 | F11: =IF(E11="","",IMAGE(E11)) | S11: =IF($C11="","",$I11*$R11) | T11: =IF($C11="","",(IF($N11="Purchased",$H11,0)+$Q11)) | U11: =IF($C11="","",$S11-$T11) | V11: =IF(OR($C11="",$I11=0),"",CEILING($T11/$I11,1))
A12: W011 | F12: =IF(E12="","",IMAGE(E12)) | S12: =IF($C12="","",$I12*$R12) | T12: =IF($C12="","",(IF($N12="Purchased",$H12,0)+$Q12)) | U12: =IF($C12="","",$S12-$T12) | V12: =IF(OR($C12="",$I12=0),"",CEILING($T12/$I12,1))
A13: W012 | F13: =IF(E13="","",IMAGE(E13)) | S13: =IF($C13="","",$I13*$R13) | T13: =IF($C13="","",(IF($N13="Purchased",$H13,0)+$Q13)) | U13: =IF($C13="","",$S13-$T13) | V13: =IF(OR($C13="",$I13=0),"",CEILING($T13/$I13,1))
A14: W013 | F14: =IF(E14="","",IMAGE(E14)) | S14: =IF($C14="","",$I14*$R14) | T14: =IF($C14="","",(IF($N14="Purchased",$H14,0)+$Q14)) | U14: =IF($C14="","",$S14-$T14) | V14: =IF(OR($C14="",$I14=0),"",CEILING($T14/$I14,1))
... A500: W499 | F500: =IF(E500="","",IMAGE(E500)) | S500: =IF($C500="","",$I500*$R500) | T500: =IF($C500="","",(IF($N500="Purchased",$H500,0)+$Q500)) | U500: =IF($C500="","",$S500-$T500) | V500: =IF(OR($C500="",$I500=0),"",CEILING($T500/$I500,1))

Sheet Wardrobe View
A1: Select wardrobe:
A3: Matching items (auto):
A5: Item ID | B5: Wardrobe Name | C5: Item Name | D5: Category | E5: Image URL | F5: Image | G5: Item Link | H5: Cost of Item ($) | I5: Rental Fee ($) | J5: Condition | K5: Size | L5: Color | M5: Brand | N5: Purchase Status | O5: Status | P5: Date Added | Q5: Extra Costs ($) | R5: Times Rented | S5: Total Revenue ($) | T5: Total Cost ($) | U5: Profit ($) | V5: Break-even Rentals | W5: Notes
A6: =IF($B$1="","",FILTER(Inventory!A2:W500,Inventory!B2:B500=$B$1,"No matches"))

Sheet Dashboard
A1: Dashboard
A2: Tip: Add items in Inventory. Dashboard updates automatically.
A3: Wardrobe | B3: # Items | C3: Total Revenue ($) | D3: Total Profit ($) | E3: Avg Rental Fee ($)
A4: =SORT(UNIQUE(FILTER(Inventory!B2:B500,Inventory!B2:B500<>""))) | B4: =IF(A4="","",COUNTIF(Inventory!B:B,A4)) | C4: =IF(A4="","",SUMIF(Inventory!B:B,A4,Inventory!S:S)) | D4: =IF(A4="","",SUMIF(Inventory!B:B,A4,Inventory!U:U)) | E4: =IF(A4="","",AVERAGEIF(Inventory!B:B,A4,Inventory!I:I))
